2023-11-28 16:52:54,158 django.utils.autoreload INFO     Watching for file changes with StatReloader
2023-11-28 16:53:20,114 django.utils.autoreload INFO     C:\Users\Nick\Desktop\mytestprj\advert\advert\settings.py changed, reloading.
2023-11-28 16:53:24,039 django.utils.autoreload INFO     Watching for file changes with StatReloader
2023-11-28 16:53:25,687 django.request WARNING  Not Found: /
2023-11-28 16:10:55,867 django.utils.autoreload INFO     Watching for file changes with StatReloader
2023-11-28 16:20:08,262 django.utils.autoreload INFO     /app/advert/settings.py changed, reloading.
2023-11-28 16:20:09,052 django.utils.autoreload INFO     Watching for file changes with StatReloader
2023-11-28 16:20:30,776 django.utils.autoreload INFO     Watching for file changes with StatReloader
2023-11-28 16:21:02,820 django.request WARNING  Not Found: /
2023-11-28 16:21:05,329 django.request ERROR    Internal Server Error: /admin/
Traceback (most recent call last):
  File "/usr/local/lib/python3.8/site-packages/django/contrib/sessions/backends/base.py", line 187, in _get_session
    return self._session_cache
AttributeError: 'SessionStore' object has no attribute '_session_cache'

During handling of the above exception, another exception occurred:

Traceback (most recent call last):
  File "/usr/local/lib/python3.8/site-packages/django/db/backends/utils.py", line 89, in _execute
    return self.cursor.execute(sql, params)
psycopg2.errors.UndefinedTable: relation "django_session" does not exist
LINE 1: ...ession_data", "django_session"."expire_date" FROM "django_se...
                                                             ^


The above exception was the direct cause of the following exception:

Traceback (most recent call last):
  File "/usr/local/lib/python3.8/site-packages/django/core/handlers/exception.py", line 55, in inner
    response = get_response(request)
  File "/usr/local/lib/python3.8/site-packages/django/core/handlers/base.py", line 197, in _get_response
    response = wrapped_callback(request, *callback_args, **callback_kwargs)
  File "/usr/local/lib/python3.8/site-packages/django/contrib/admin/sites.py", line 261, in wrapper
    return self.admin_view(view, cacheable)(*args, **kwargs)
  File "/usr/local/lib/python3.8/site-packages/django/utils/decorators.py", line 134, in _wrapper_view
    response = view_func(request, *args, **kwargs)
  File "/usr/local/lib/python3.8/site-packages/django/views/decorators/cache.py", line 62, in _wrapper_view_func
    response = view_func(request, *args, **kwargs)
  File "/usr/local/lib/python3.8/site-packages/django/contrib/admin/sites.py", line 230, in inner
    if not self.has_permission(request):
  File "/usr/local/lib/python3.8/site-packages/django/contrib/admin/sites.py", line 203, in has_permission
    return request.user.is_active and request.user.is_staff
  File "/usr/local/lib/python3.8/site-packages/django/utils/functional.py", line 266, in inner
    self._setup()
  File "/usr/local/lib/python3.8/site-packages/django/utils/functional.py", line 419, in _setup
    self._wrapped = self._setupfunc()
  File "/usr/local/lib/python3.8/site-packages/django/contrib/auth/middleware.py", line 25, in <lambda>
    request.user = SimpleLazyObject(lambda: get_user(request))
  File "/usr/local/lib/python3.8/site-packages/django/contrib/auth/middleware.py", line 11, in get_user
    request._cached_user = auth.get_user(request)
  File "/usr/local/lib/python3.8/site-packages/django/contrib/auth/__init__.py", line 191, in get_user
    user_id = _get_user_session_key(request)
  File "/usr/local/lib/python3.8/site-packages/django/contrib/auth/__init__.py", line 60, in _get_user_session_key
    return get_user_model()._meta.pk.to_python(request.session[SESSION_KEY])
  File "/usr/local/lib/python3.8/site-packages/django/contrib/sessions/backends/base.py", line 53, in __getitem__
    return self._session[key]
  File "/usr/local/lib/python3.8/site-packages/django/contrib/sessions/backends/base.py", line 192, in _get_session
    self._session_cache = self.load()
  File "/usr/local/lib/python3.8/site-packages/django/contrib/sessions/backends/db.py", line 42, in load
    s = self._get_session_from_db()
  File "/usr/local/lib/python3.8/site-packages/django/contrib/sessions/backends/db.py", line 32, in _get_session_from_db
    return self.model.objects.get(
  File "/usr/local/lib/python3.8/site-packages/django/db/models/manager.py", line 87, in manager_method
    return getattr(self.get_queryset(), name)(*args, **kwargs)
  File "/usr/local/lib/python3.8/site-packages/django/db/models/query.py", line 633, in get
    num = len(clone)
  File "/usr/local/lib/python3.8/site-packages/django/db/models/query.py", line 380, in __len__
    self._fetch_all()
  File "/usr/local/lib/python3.8/site-packages/django/db/models/query.py", line 1881, in _fetch_all
    self._result_cache = list(self._iterable_class(self))
  File "/usr/local/lib/python3.8/site-packages/django/db/models/query.py", line 91, in __iter__
    results = compiler.execute_sql(
  File "/usr/local/lib/python3.8/site-packages/django/db/models/sql/compiler.py", line 1562, in execute_sql
    cursor.execute(sql, params)
  File "/usr/local/lib/python3.8/site-packages/django/db/backends/utils.py", line 102, in execute
    return super().execute(sql, params)
  File "/usr/local/lib/python3.8/site-packages/django/db/backends/utils.py", line 67, in execute
    return self._execute_with_wrappers(
  File "/usr/local/lib/python3.8/site-packages/django/db/backends/utils.py", line 80, in _execute_with_wrappers
    return executor(sql, params, many, context)
  File "/usr/local/lib/python3.8/site-packages/django/db/backends/utils.py", line 89, in _execute
    return self.cursor.execute(sql, params)
  File "/usr/local/lib/python3.8/site-packages/django/db/utils.py", line 91, in __exit__
    raise dj_exc_value.with_traceback(traceback) from exc_value
  File "/usr/local/lib/python3.8/site-packages/django/db/backends/utils.py", line 89, in _execute
    return self.cursor.execute(sql, params)
django.db.utils.ProgrammingError: relation "django_session" does not exist
LINE 1: ...ession_data", "django_session"."expire_date" FROM "django_se...
                                                             ^

2023-11-28 16:21:05,562 django.request ERROR    Internal Server Error: /admin/
Traceback (most recent call last):
  File "/usr/local/lib/python3.8/site-packages/django/contrib/sessions/backends/base.py", line 187, in _get_session
    return self._session_cache
AttributeError: 'SessionStore' object has no attribute '_session_cache'

During handling of the above exception, another exception occurred:

Traceback (most recent call last):
  File "/usr/local/lib/python3.8/site-packages/django/db/backends/utils.py", line 89, in _execute
    return self.cursor.execute(sql, params)
psycopg2.errors.UndefinedTable: relation "django_session" does not exist
LINE 1: ...ession_data", "django_session"."expire_date" FROM "django_se...
                                                             ^


The above exception was the direct cause of the following exception:

Traceback (most recent call last):
  File "/usr/local/lib/python3.8/site-packages/django/core/handlers/exception.py", line 55, in inner
    response = get_response(request)
  File "/usr/local/lib/python3.8/site-packages/django/core/handlers/base.py", line 197, in _get_response
    response = wrapped_callback(request, *callback_args, **callback_kwargs)
  File "/usr/local/lib/python3.8/site-packages/django/contrib/admin/sites.py", line 261, in wrapper
    return self.admin_view(view, cacheable)(*args, **kwargs)
  File "/usr/local/lib/python3.8/site-packages/django/utils/decorators.py", line 134, in _wrapper_view
    response = view_func(request, *args, **kwargs)
  File "/usr/local/lib/python3.8/site-packages/django/views/decorators/cache.py", line 62, in _wrapper_view_func
    response = view_func(request, *args, **kwargs)
  File "/usr/local/lib/python3.8/site-packages/django/contrib/admin/sites.py", line 230, in inner
    if not self.has_permission(request):
  File "/usr/local/lib/python3.8/site-packages/django/contrib/admin/sites.py", line 203, in has_permission
    return request.user.is_active and request.user.is_staff
  File "/usr/local/lib/python3.8/site-packages/django/utils/functional.py", line 266, in inner
    self._setup()
  File "/usr/local/lib/python3.8/site-packages/django/utils/functional.py", line 419, in _setup
    self._wrapped = self._setupfunc()
  File "/usr/local/lib/python3.8/site-packages/django/contrib/auth/middleware.py", line 25, in <lambda>
    request.user = SimpleLazyObject(lambda: get_user(request))
  File "/usr/local/lib/python3.8/site-packages/django/contrib/auth/middleware.py", line 11, in get_user
    request._cached_user = auth.get_user(request)
  File "/usr/local/lib/python3.8/site-packages/django/contrib/auth/__init__.py", line 191, in get_user
    user_id = _get_user_session_key(request)
  File "/usr/local/lib/python3.8/site-packages/django/contrib/auth/__init__.py", line 60, in _get_user_session_key
    return get_user_model()._meta.pk.to_python(request.session[SESSION_KEY])
  File "/usr/local/lib/python3.8/site-packages/django/contrib/sessions/backends/base.py", line 53, in __getitem__
    return self._session[key]
  File "/usr/local/lib/python3.8/site-packages/django/contrib/sessions/backends/base.py", line 192, in _get_session
    self._session_cache = self.load()
  File "/usr/local/lib/python3.8/site-packages/django/contrib/sessions/backends/db.py", line 42, in load
    s = self._get_session_from_db()
  File "/usr/local/lib/python3.8/site-packages/django/contrib/sessions/backends/db.py", line 32, in _get_session_from_db
    return self.model.objects.get(
  File "/usr/local/lib/python3.8/site-packages/django/db/models/manager.py", line 87, in manager_method
    return getattr(self.get_queryset(), name)(*args, **kwargs)
  File "/usr/local/lib/python3.8/site-packages/django/db/models/query.py", line 633, in get
    num = len(clone)
  File "/usr/local/lib/python3.8/site-packages/django/db/models/query.py", line 380, in __len__
    self._fetch_all()
  File "/usr/local/lib/python3.8/site-packages/django/db/models/query.py", line 1881, in _fetch_all
    self._result_cache = list(self._iterable_class(self))
  File "/usr/local/lib/python3.8/site-packages/django/db/models/query.py", line 91, in __iter__
    results = compiler.execute_sql(
  File "/usr/local/lib/python3.8/site-packages/django/db/models/sql/compiler.py", line 1562, in execute_sql
    cursor.execute(sql, params)
  File "/usr/local/lib/python3.8/site-packages/django/db/backends/utils.py", line 102, in execute
    return super().execute(sql, params)
  File "/usr/local/lib/python3.8/site-packages/django/db/backends/utils.py", line 67, in execute
    return self._execute_with_wrappers(
  File "/usr/local/lib/python3.8/site-packages/django/db/backends/utils.py", line 80, in _execute_with_wrappers
    return executor(sql, params, many, context)
  File "/usr/local/lib/python3.8/site-packages/django/db/backends/utils.py", line 89, in _execute
    return self.cursor.execute(sql, params)
  File "/usr/local/lib/python3.8/site-packages/django/db/utils.py", line 91, in __exit__
    raise dj_exc_value.with_traceback(traceback) from exc_value
  File "/usr/local/lib/python3.8/site-packages/django/db/backends/utils.py", line 89, in _execute
    return self.cursor.execute(sql, params)
django.db.utils.ProgrammingError: relation "django_session" does not exist
LINE 1: ...ession_data", "django_session"."expire_date" FROM "django_se...
                                                             ^

2023-11-29 08:44:24,457 django.utils.autoreload INFO     Watching for file changes with StatReloader
2023-11-29 09:11:09,349 django.utils.autoreload INFO     Watching for file changes with StatReloader
2023-11-29 09:11:35,041 django.utils.autoreload INFO     Watching for file changes with StatReloader
2023-11-29 09:13:34,053 django.request WARNING  Not Found: /
2023-11-29 09:13:34,182 django.request WARNING  Not Found: /favicon.ico
2024-01-11 17:49:12,085 django.utils.autoreload INFO     Watching for file changes with StatReloader
2024-01-11 17:49:14,163 django.request WARNING  Not Found: /
2024-01-11 17:51:35,770 django.utils.autoreload INFO     Watching for file changes with StatReloader
2024-01-11 17:51:37,254 django.request WARNING  Not Found: /
2024-01-14 19:12:53,862 django.utils.autoreload INFO     Watching for file changes with StatReloader
2024-01-14 19:12:56,059 django.request WARNING  Not Found: /
2024-01-14 19:12:56,136 django.request WARNING  Not Found: /favicon.ico
2024-01-14 19:15:16,683 PIL.Image    DEBUG    Importing BlpImagePlugin
2024-01-14 19:15:16,683 PIL.Image    DEBUG    Importing BmpImagePlugin
2024-01-14 19:15:16,683 PIL.Image    DEBUG    Importing BufrStubImagePlugin
2024-01-14 19:15:16,683 PIL.Image    DEBUG    Importing CurImagePlugin
2024-01-14 19:15:16,683 PIL.Image    DEBUG    Importing DcxImagePlugin
2024-01-14 19:15:16,683 PIL.Image    DEBUG    Importing DdsImagePlugin
2024-01-14 19:15:16,683 PIL.Image    DEBUG    Importing EpsImagePlugin
2024-01-14 19:15:16,699 PIL.Image    DEBUG    Importing FitsImagePlugin
2024-01-14 19:15:16,699 PIL.Image    DEBUG    Importing FliImagePlugin
2024-01-14 19:15:16,699 PIL.Image    DEBUG    Importing FpxImagePlugin
2024-01-14 19:15:16,699 PIL.Image    DEBUG    Image: failed to import FpxImagePlugin: No module named 'olefile'
2024-01-14 19:15:16,699 PIL.Image    DEBUG    Importing FtexImagePlugin
2024-01-14 19:15:16,699 PIL.Image    DEBUG    Importing GbrImagePlugin
2024-01-14 19:15:16,699 PIL.Image    DEBUG    Importing GifImagePlugin
2024-01-14 19:15:16,699 PIL.Image    DEBUG    Importing GribStubImagePlugin
2024-01-14 19:15:16,699 PIL.Image    DEBUG    Importing Hdf5StubImagePlugin
2024-01-14 19:15:16,699 PIL.Image    DEBUG    Importing IcnsImagePlugin
2024-01-14 19:15:16,715 PIL.Image    DEBUG    Importing IcoImagePlugin
2024-01-14 19:15:16,717 PIL.Image    DEBUG    Importing ImImagePlugin
2024-01-14 19:15:16,717 PIL.Image    DEBUG    Importing ImtImagePlugin
2024-01-14 19:15:16,717 PIL.Image    DEBUG    Importing IptcImagePlugin
2024-01-14 19:15:16,717 PIL.Image    DEBUG    Importing JpegImagePlugin
2024-01-14 19:15:16,717 PIL.Image    DEBUG    Importing Jpeg2KImagePlugin
2024-01-14 19:15:16,717 PIL.Image    DEBUG    Importing McIdasImagePlugin
2024-01-14 19:15:16,717 PIL.Image    DEBUG    Importing MicImagePlugin
2024-01-14 19:15:16,717 PIL.Image    DEBUG    Image: failed to import MicImagePlugin: No module named 'olefile'
2024-01-14 19:15:16,717 PIL.Image    DEBUG    Importing MpegImagePlugin
2024-01-14 19:15:16,717 PIL.Image    DEBUG    Importing MpoImagePlugin
2024-01-14 19:15:16,733 PIL.Image    DEBUG    Importing MspImagePlugin
2024-01-14 19:15:16,733 PIL.Image    DEBUG    Importing PalmImagePlugin
2024-01-14 19:15:16,733 PIL.Image    DEBUG    Importing PcdImagePlugin
2024-01-14 19:15:16,733 PIL.Image    DEBUG    Importing PcxImagePlugin
2024-01-14 19:15:16,733 PIL.Image    DEBUG    Importing PdfImagePlugin
2024-01-14 19:15:16,749 PIL.Image    DEBUG    Importing PixarImagePlugin
2024-01-14 19:15:16,750 PIL.Image    DEBUG    Importing PngImagePlugin
2024-01-14 19:15:16,750 PIL.Image    DEBUG    Importing PpmImagePlugin
2024-01-14 19:15:16,750 PIL.Image    DEBUG    Importing PsdImagePlugin
2024-01-14 19:15:16,750 PIL.Image    DEBUG    Importing QoiImagePlugin
2024-01-14 19:15:16,750 PIL.Image    DEBUG    Importing SgiImagePlugin
2024-01-14 19:15:16,750 PIL.Image    DEBUG    Importing SpiderImagePlugin
2024-01-14 19:15:16,750 PIL.Image    DEBUG    Importing SunImagePlugin
2024-01-14 19:15:16,750 PIL.Image    DEBUG    Importing TgaImagePlugin
2024-01-14 19:15:16,750 PIL.Image    DEBUG    Importing TiffImagePlugin
2024-01-14 19:15:16,750 PIL.Image    DEBUG    Importing WebPImagePlugin
2024-01-14 19:15:16,750 PIL.Image    DEBUG    Importing WmfImagePlugin
2024-01-14 19:15:16,750 PIL.Image    DEBUG    Importing XbmImagePlugin
2024-01-14 19:15:16,766 PIL.Image    DEBUG    Importing XpmImagePlugin
2024-01-14 19:15:16,766 PIL.Image    DEBUG    Importing XVThumbImagePlugin
2024-01-14 19:21:10,390 django.request WARNING  Not Found: /user/
2024-01-14 19:21:18,013 django.request WARNING  Not Found: /user/registrations
2024-01-14 19:21:27,205 django.request WARNING  Not Found: /api/user/registrations
2024-01-14 19:21:58,358 django.request WARNING  Not Found: /api/user/register
2024-01-14 19:22:09,759 django.request WARNING  Method Not Allowed: /api/users/register/
2024-01-14 19:25:50,543 django.request WARNING  Bad Request: /api/users/register/
2024-01-14 19:26:36,535 django.request WARNING  Not Found: /api/register
2024-01-14 19:26:42,144 django.request WARNING  Method Not Allowed: /api/users/register/
2024-01-14 19:26:56,384 django.request WARNING  Not Found: /api/register
2024-01-14 19:27:01,206 django.request WARNING  Not Found: /api/register
2024-01-14 19:27:04,973 django.request WARNING  Not Found: /api/register
2024-01-14 19:27:06,488 django.request WARNING  Method Not Allowed: /api/users/register/
2024-01-14 19:27:07,042 django.request WARNING  Method Not Allowed: /api/users/register/
2024-01-14 19:27:07,201 django.request WARNING  Method Not Allowed: /api/users/register/
2024-01-14 19:28:28,174 django.request WARNING  Bad Request: /api/users/register/
2024-01-14 19:29:14,725 django.request WARNING  Bad Request: /api/users/register/
2024-01-14 19:29:28,617 django.request WARNING  Method Not Allowed: /api/users/register/
2024-01-14 19:29:30,367 django.request WARNING  Method Not Allowed: /api/users/register/
2024-01-14 19:29:31,509 django.request WARNING  Method Not Allowed: /api/users/register/
2024-01-14 19:29:31,686 django.request WARNING  Method Not Allowed: /api/users/register/
2024-01-14 19:30:00,403 django.request WARNING  Method Not Allowed: /api/users/register/
2024-01-14 19:30:01,198 django.request WARNING  Method Not Allowed: /api/users/register/
2024-01-14 19:30:01,378 django.request WARNING  Method Not Allowed: /api/users/register/
2024-01-16 14:42:02,821 django.utils.autoreload INFO     Watching for file changes with StatReloader
2024-01-16 14:42:08,134 django.request WARNING  Not Found: /
2024-01-16 14:42:08,243 django.request WARNING  Not Found: /favicon.ico
2024-01-16 14:44:36,808 django.utils.autoreload INFO     Watching for file changes with StatReloader
2024-01-16 14:44:41,496 django.request WARNING  Not Found: /
2024-01-16 14:50:04,292 PIL.Image    DEBUG    Importing BlpImagePlugin
2024-01-16 14:50:04,292 PIL.Image    DEBUG    Importing BmpImagePlugin
2024-01-16 14:50:04,292 PIL.Image    DEBUG    Importing BufrStubImagePlugin
2024-01-16 14:50:04,307 PIL.Image    DEBUG    Importing CurImagePlugin
2024-01-16 14:50:04,309 PIL.Image    DEBUG    Importing DcxImagePlugin
2024-01-16 14:50:04,309 PIL.Image    DEBUG    Importing DdsImagePlugin
2024-01-16 14:50:04,309 PIL.Image    DEBUG    Importing EpsImagePlugin
2024-01-16 14:50:04,309 PIL.Image    DEBUG    Importing FitsImagePlugin
2024-01-16 14:50:04,326 PIL.Image    DEBUG    Importing FliImagePlugin
2024-01-16 14:50:04,326 PIL.Image    DEBUG    Importing FpxImagePlugin
2024-01-16 14:50:04,326 PIL.Image    DEBUG    Image: failed to import FpxImagePlugin: No module named 'olefile'
2024-01-16 14:50:04,326 PIL.Image    DEBUG    Importing FtexImagePlugin
2024-01-16 14:50:04,326 PIL.Image    DEBUG    Importing GbrImagePlugin
2024-01-16 14:50:04,326 PIL.Image    DEBUG    Importing GifImagePlugin
2024-01-16 14:50:04,326 PIL.Image    DEBUG    Importing GribStubImagePlugin
2024-01-16 14:50:04,326 PIL.Image    DEBUG    Importing Hdf5StubImagePlugin
2024-01-16 14:50:04,326 PIL.Image    DEBUG    Importing IcnsImagePlugin
2024-01-16 14:50:04,342 PIL.Image    DEBUG    Importing IcoImagePlugin
2024-01-16 14:50:04,342 PIL.Image    DEBUG    Importing ImImagePlugin
2024-01-16 14:50:04,342 PIL.Image    DEBUG    Importing ImtImagePlugin
2024-01-16 14:50:04,342 PIL.Image    DEBUG    Importing IptcImagePlugin
2024-01-16 14:50:04,342 PIL.Image    DEBUG    Importing JpegImagePlugin
2024-01-16 14:50:04,342 PIL.Image    DEBUG    Importing Jpeg2KImagePlugin
2024-01-16 14:50:04,342 PIL.Image    DEBUG    Importing McIdasImagePlugin
2024-01-16 14:50:04,342 PIL.Image    DEBUG    Importing MicImagePlugin
2024-01-16 14:50:04,359 PIL.Image    DEBUG    Image: failed to import MicImagePlugin: No module named 'olefile'
2024-01-16 14:50:04,359 PIL.Image    DEBUG    Importing MpegImagePlugin
2024-01-16 14:50:04,359 PIL.Image    DEBUG    Importing MpoImagePlugin
2024-01-16 14:50:04,359 PIL.Image    DEBUG    Importing MspImagePlugin
2024-01-16 14:50:04,373 PIL.Image    DEBUG    Importing PalmImagePlugin
2024-01-16 14:50:04,376 PIL.Image    DEBUG    Importing PcdImagePlugin
2024-01-16 14:50:04,376 PIL.Image    DEBUG    Importing PcxImagePlugin
2024-01-16 14:50:04,376 PIL.Image    DEBUG    Importing PdfImagePlugin
2024-01-16 14:50:04,392 PIL.Image    DEBUG    Importing PixarImagePlugin
2024-01-16 14:50:04,392 PIL.Image    DEBUG    Importing PngImagePlugin
2024-01-16 14:50:04,392 PIL.Image    DEBUG    Importing PpmImagePlugin
2024-01-16 14:50:04,392 PIL.Image    DEBUG    Importing PsdImagePlugin
2024-01-16 14:50:04,392 PIL.Image    DEBUG    Importing QoiImagePlugin
2024-01-16 14:50:04,392 PIL.Image    DEBUG    Importing SgiImagePlugin
2024-01-16 14:50:04,392 PIL.Image    DEBUG    Importing SpiderImagePlugin
2024-01-16 14:50:04,392 PIL.Image    DEBUG    Importing SunImagePlugin
2024-01-16 14:50:04,409 PIL.Image    DEBUG    Importing TgaImagePlugin
2024-01-16 14:50:04,409 PIL.Image    DEBUG    Importing TiffImagePlugin
2024-01-16 14:50:04,409 PIL.Image    DEBUG    Importing WebPImagePlugin
2024-01-16 14:50:04,409 PIL.Image    DEBUG    Importing WmfImagePlugin
2024-01-16 14:50:04,409 PIL.Image    DEBUG    Importing XbmImagePlugin
2024-01-16 14:50:04,409 PIL.Image    DEBUG    Importing XpmImagePlugin
2024-01-16 14:50:04,425 PIL.Image    DEBUG    Importing XVThumbImagePlugin
