2023-11-28 16:52:54,158 django.utils.autoreload INFO     Watching for file changes with StatReloader
2023-11-28 16:53:20,114 django.utils.autoreload INFO     C:\Users\Nick\Desktop\mytestprj\advert\advert\settings.py changed, reloading.
2023-11-28 16:53:24,039 django.utils.autoreload INFO     Watching for file changes with StatReloader
2023-11-28 16:53:25,687 django.request WARNING  Not Found: /
2023-11-28 16:10:55,867 django.utils.autoreload INFO     Watching for file changes with StatReloader
2023-11-28 16:20:08,262 django.utils.autoreload INFO     /app/advert/settings.py changed, reloading.
2023-11-28 16:20:09,052 django.utils.autoreload INFO     Watching for file changes with StatReloader
2023-11-28 16:20:30,776 django.utils.autoreload INFO     Watching for file changes with StatReloader
2023-11-28 16:21:02,820 django.request WARNING  Not Found: /
2023-11-28 16:21:05,329 django.request ERROR    Internal Server Error: /admin/
Traceback (most recent call last):
  File "/usr/local/lib/python3.8/site-packages/django/contrib/sessions/backends/base.py", line 187, in _get_session
    return self._session_cache
AttributeError: 'SessionStore' object has no attribute '_session_cache'

During handling of the above exception, another exception occurred:

Traceback (most recent call last):
  File "/usr/local/lib/python3.8/site-packages/django/db/backends/utils.py", line 89, in _execute
    return self.cursor.execute(sql, params)
psycopg2.errors.UndefinedTable: relation "django_session" does not exist
LINE 1: ...ession_data", "django_session"."expire_date" FROM "django_se...
                                                             ^


The above exception was the direct cause of the following exception:

Traceback (most recent call last):
  File "/usr/local/lib/python3.8/site-packages/django/core/handlers/exception.py", line 55, in inner
    response = get_response(request)
  File "/usr/local/lib/python3.8/site-packages/django/core/handlers/base.py", line 197, in _get_response
    response = wrapped_callback(request, *callback_args, **callback_kwargs)
  File "/usr/local/lib/python3.8/site-packages/django/contrib/admin/sites.py", line 261, in wrapper
    return self.admin_view(view, cacheable)(*args, **kwargs)
  File "/usr/local/lib/python3.8/site-packages/django/utils/decorators.py", line 134, in _wrapper_view
    response = view_func(request, *args, **kwargs)
  File "/usr/local/lib/python3.8/site-packages/django/views/decorators/cache.py", line 62, in _wrapper_view_func
    response = view_func(request, *args, **kwargs)
  File "/usr/local/lib/python3.8/site-packages/django/contrib/admin/sites.py", line 230, in inner
    if not self.has_permission(request):
  File "/usr/local/lib/python3.8/site-packages/django/contrib/admin/sites.py", line 203, in has_permission
    return request.user.is_active and request.user.is_staff
  File "/usr/local/lib/python3.8/site-packages/django/utils/functional.py", line 266, in inner
    self._setup()
  File "/usr/local/lib/python3.8/site-packages/django/utils/functional.py", line 419, in _setup
    self._wrapped = self._setupfunc()
  File "/usr/local/lib/python3.8/site-packages/django/contrib/auth/middleware.py", line 25, in <lambda>
    request.user = SimpleLazyObject(lambda: get_user(request))
  File "/usr/local/lib/python3.8/site-packages/django/contrib/auth/middleware.py", line 11, in get_user
    request._cached_user = auth.get_user(request)
  File "/usr/local/lib/python3.8/site-packages/django/contrib/auth/__init__.py", line 191, in get_user
    user_id = _get_user_session_key(request)
  File "/usr/local/lib/python3.8/site-packages/django/contrib/auth/__init__.py", line 60, in _get_user_session_key
    return get_user_model()._meta.pk.to_python(request.session[SESSION_KEY])
  File "/usr/local/lib/python3.8/site-packages/django/contrib/sessions/backends/base.py", line 53, in __getitem__
    return self._session[key]
  File "/usr/local/lib/python3.8/site-packages/django/contrib/sessions/backends/base.py", line 192, in _get_session
    self._session_cache = self.load()
  File "/usr/local/lib/python3.8/site-packages/django/contrib/sessions/backends/db.py", line 42, in load
    s = self._get_session_from_db()
  File "/usr/local/lib/python3.8/site-packages/django/contrib/sessions/backends/db.py", line 32, in _get_session_from_db
    return self.model.objects.get(
  File "/usr/local/lib/python3.8/site-packages/django/db/models/manager.py", line 87, in manager_method
    return getattr(self.get_queryset(), name)(*args, **kwargs)
  File "/usr/local/lib/python3.8/site-packages/django/db/models/query.py", line 633, in get
    num = len(clone)
  File "/usr/local/lib/python3.8/site-packages/django/db/models/query.py", line 380, in __len__
    self._fetch_all()
  File "/usr/local/lib/python3.8/site-packages/django/db/models/query.py", line 1881, in _fetch_all
    self._result_cache = list(self._iterable_class(self))
  File "/usr/local/lib/python3.8/site-packages/django/db/models/query.py", line 91, in __iter__
    results = compiler.execute_sql(
  File "/usr/local/lib/python3.8/site-packages/django/db/models/sql/compiler.py", line 1562, in execute_sql
    cursor.execute(sql, params)
  File "/usr/local/lib/python3.8/site-packages/django/db/backends/utils.py", line 102, in execute
    return super().execute(sql, params)
  File "/usr/local/lib/python3.8/site-packages/django/db/backends/utils.py", line 67, in execute
    return self._execute_with_wrappers(
  File "/usr/local/lib/python3.8/site-packages/django/db/backends/utils.py", line 80, in _execute_with_wrappers
    return executor(sql, params, many, context)
  File "/usr/local/lib/python3.8/site-packages/django/db/backends/utils.py", line 89, in _execute
    return self.cursor.execute(sql, params)
  File "/usr/local/lib/python3.8/site-packages/django/db/utils.py", line 91, in __exit__
    raise dj_exc_value.with_traceback(traceback) from exc_value
  File "/usr/local/lib/python3.8/site-packages/django/db/backends/utils.py", line 89, in _execute
    return self.cursor.execute(sql, params)
django.db.utils.ProgrammingError: relation "django_session" does not exist
LINE 1: ...ession_data", "django_session"."expire_date" FROM "django_se...
                                                             ^

2023-11-28 16:21:05,562 django.request ERROR    Internal Server Error: /admin/
Traceback (most recent call last):
  File "/usr/local/lib/python3.8/site-packages/django/contrib/sessions/backends/base.py", line 187, in _get_session
    return self._session_cache
AttributeError: 'SessionStore' object has no attribute '_session_cache'

During handling of the above exception, another exception occurred:

Traceback (most recent call last):
  File "/usr/local/lib/python3.8/site-packages/django/db/backends/utils.py", line 89, in _execute
    return self.cursor.execute(sql, params)
psycopg2.errors.UndefinedTable: relation "django_session" does not exist
LINE 1: ...ession_data", "django_session"."expire_date" FROM "django_se...
                                                             ^


The above exception was the direct cause of the following exception:

Traceback (most recent call last):
  File "/usr/local/lib/python3.8/site-packages/django/core/handlers/exception.py", line 55, in inner
    response = get_response(request)
  File "/usr/local/lib/python3.8/site-packages/django/core/handlers/base.py", line 197, in _get_response
    response = wrapped_callback(request, *callback_args, **callback_kwargs)
  File "/usr/local/lib/python3.8/site-packages/django/contrib/admin/sites.py", line 261, in wrapper
    return self.admin_view(view, cacheable)(*args, **kwargs)
  File "/usr/local/lib/python3.8/site-packages/django/utils/decorators.py", line 134, in _wrapper_view
    response = view_func(request, *args, **kwargs)
  File "/usr/local/lib/python3.8/site-packages/django/views/decorators/cache.py", line 62, in _wrapper_view_func
    response = view_func(request, *args, **kwargs)
  File "/usr/local/lib/python3.8/site-packages/django/contrib/admin/sites.py", line 230, in inner
    if not self.has_permission(request):
  File "/usr/local/lib/python3.8/site-packages/django/contrib/admin/sites.py", line 203, in has_permission
    return request.user.is_active and request.user.is_staff
  File "/usr/local/lib/python3.8/site-packages/django/utils/functional.py", line 266, in inner
    self._setup()
  File "/usr/local/lib/python3.8/site-packages/django/utils/functional.py", line 419, in _setup
    self._wrapped = self._setupfunc()
  File "/usr/local/lib/python3.8/site-packages/django/contrib/auth/middleware.py", line 25, in <lambda>
    request.user = SimpleLazyObject(lambda: get_user(request))
  File "/usr/local/lib/python3.8/site-packages/django/contrib/auth/middleware.py", line 11, in get_user
    request._cached_user = auth.get_user(request)
  File "/usr/local/lib/python3.8/site-packages/django/contrib/auth/__init__.py", line 191, in get_user
    user_id = _get_user_session_key(request)
  File "/usr/local/lib/python3.8/site-packages/django/contrib/auth/__init__.py", line 60, in _get_user_session_key
    return get_user_model()._meta.pk.to_python(request.session[SESSION_KEY])
  File "/usr/local/lib/python3.8/site-packages/django/contrib/sessions/backends/base.py", line 53, in __getitem__
    return self._session[key]
  File "/usr/local/lib/python3.8/site-packages/django/contrib/sessions/backends/base.py", line 192, in _get_session
    self._session_cache = self.load()
  File "/usr/local/lib/python3.8/site-packages/django/contrib/sessions/backends/db.py", line 42, in load
    s = self._get_session_from_db()
  File "/usr/local/lib/python3.8/site-packages/django/contrib/sessions/backends/db.py", line 32, in _get_session_from_db
    return self.model.objects.get(
  File "/usr/local/lib/python3.8/site-packages/django/db/models/manager.py", line 87, in manager_method
    return getattr(self.get_queryset(), name)(*args, **kwargs)
  File "/usr/local/lib/python3.8/site-packages/django/db/models/query.py", line 633, in get
    num = len(clone)
  File "/usr/local/lib/python3.8/site-packages/django/db/models/query.py", line 380, in __len__
    self._fetch_all()
  File "/usr/local/lib/python3.8/site-packages/django/db/models/query.py", line 1881, in _fetch_all
    self._result_cache = list(self._iterable_class(self))
  File "/usr/local/lib/python3.8/site-packages/django/db/models/query.py", line 91, in __iter__
    results = compiler.execute_sql(
  File "/usr/local/lib/python3.8/site-packages/django/db/models/sql/compiler.py", line 1562, in execute_sql
    cursor.execute(sql, params)
  File "/usr/local/lib/python3.8/site-packages/django/db/backends/utils.py", line 102, in execute
    return super().execute(sql, params)
  File "/usr/local/lib/python3.8/site-packages/django/db/backends/utils.py", line 67, in execute
    return self._execute_with_wrappers(
  File "/usr/local/lib/python3.8/site-packages/django/db/backends/utils.py", line 80, in _execute_with_wrappers
    return executor(sql, params, many, context)
  File "/usr/local/lib/python3.8/site-packages/django/db/backends/utils.py", line 89, in _execute
    return self.cursor.execute(sql, params)
  File "/usr/local/lib/python3.8/site-packages/django/db/utils.py", line 91, in __exit__
    raise dj_exc_value.with_traceback(traceback) from exc_value
  File "/usr/local/lib/python3.8/site-packages/django/db/backends/utils.py", line 89, in _execute
    return self.cursor.execute(sql, params)
django.db.utils.ProgrammingError: relation "django_session" does not exist
LINE 1: ...ession_data", "django_session"."expire_date" FROM "django_se...
                                                             ^

2023-11-29 08:44:24,457 django.utils.autoreload INFO     Watching for file changes with StatReloader
2023-11-29 09:11:09,349 django.utils.autoreload INFO     Watching for file changes with StatReloader
2023-11-29 09:11:35,041 django.utils.autoreload INFO     Watching for file changes with StatReloader
2023-11-29 09:13:34,053 django.request WARNING  Not Found: /
2023-11-29 09:13:34,182 django.request WARNING  Not Found: /favicon.ico
2024-01-11 17:49:12,085 django.utils.autoreload INFO     Watching for file changes with StatReloader
2024-01-11 17:49:14,163 django.request WARNING  Not Found: /
2024-01-11 17:51:35,770 django.utils.autoreload INFO     Watching for file changes with StatReloader
2024-01-11 17:51:37,254 django.request WARNING  Not Found: /
2024-01-14 19:12:53,862 django.utils.autoreload INFO     Watching for file changes with StatReloader
2024-01-14 19:12:56,059 django.request WARNING  Not Found: /
2024-01-14 19:12:56,136 django.request WARNING  Not Found: /favicon.ico
2024-01-14 19:15:16,683 PIL.Image    DEBUG    Importing BlpImagePlugin
2024-01-14 19:15:16,683 PIL.Image    DEBUG    Importing BmpImagePlugin
2024-01-14 19:15:16,683 PIL.Image    DEBUG    Importing BufrStubImagePlugin
2024-01-14 19:15:16,683 PIL.Image    DEBUG    Importing CurImagePlugin
2024-01-14 19:15:16,683 PIL.Image    DEBUG    Importing DcxImagePlugin
2024-01-14 19:15:16,683 PIL.Image    DEBUG    Importing DdsImagePlugin
2024-01-14 19:15:16,683 PIL.Image    DEBUG    Importing EpsImagePlugin
2024-01-14 19:15:16,699 PIL.Image    DEBUG    Importing FitsImagePlugin
2024-01-14 19:15:16,699 PIL.Image    DEBUG    Importing FliImagePlugin
2024-01-14 19:15:16,699 PIL.Image    DEBUG    Importing FpxImagePlugin
2024-01-14 19:15:16,699 PIL.Image    DEBUG    Image: failed to import FpxImagePlugin: No module named 'olefile'
2024-01-14 19:15:16,699 PIL.Image    DEBUG    Importing FtexImagePlugin
2024-01-14 19:15:16,699 PIL.Image    DEBUG    Importing GbrImagePlugin
2024-01-14 19:15:16,699 PIL.Image    DEBUG    Importing GifImagePlugin
2024-01-14 19:15:16,699 PIL.Image    DEBUG    Importing GribStubImagePlugin
2024-01-14 19:15:16,699 PIL.Image    DEBUG    Importing Hdf5StubImagePlugin
2024-01-14 19:15:16,699 PIL.Image    DEBUG    Importing IcnsImagePlugin
2024-01-14 19:15:16,715 PIL.Image    DEBUG    Importing IcoImagePlugin
2024-01-14 19:15:16,717 PIL.Image    DEBUG    Importing ImImagePlugin
2024-01-14 19:15:16,717 PIL.Image    DEBUG    Importing ImtImagePlugin
2024-01-14 19:15:16,717 PIL.Image    DEBUG    Importing IptcImagePlugin
2024-01-14 19:15:16,717 PIL.Image    DEBUG    Importing JpegImagePlugin
2024-01-14 19:15:16,717 PIL.Image    DEBUG    Importing Jpeg2KImagePlugin
2024-01-14 19:15:16,717 PIL.Image    DEBUG    Importing McIdasImagePlugin
2024-01-14 19:15:16,717 PIL.Image    DEBUG    Importing MicImagePlugin
2024-01-14 19:15:16,717 PIL.Image    DEBUG    Image: failed to import MicImagePlugin: No module named 'olefile'
2024-01-14 19:15:16,717 PIL.Image    DEBUG    Importing MpegImagePlugin
2024-01-14 19:15:16,717 PIL.Image    DEBUG    Importing MpoImagePlugin
2024-01-14 19:15:16,733 PIL.Image    DEBUG    Importing MspImagePlugin
2024-01-14 19:15:16,733 PIL.Image    DEBUG    Importing PalmImagePlugin
2024-01-14 19:15:16,733 PIL.Image    DEBUG    Importing PcdImagePlugin
2024-01-14 19:15:16,733 PIL.Image    DEBUG    Importing PcxImagePlugin
2024-01-14 19:15:16,733 PIL.Image    DEBUG    Importing PdfImagePlugin
2024-01-14 19:15:16,749 PIL.Image    DEBUG    Importing PixarImagePlugin
2024-01-14 19:15:16,750 PIL.Image    DEBUG    Importing PngImagePlugin
2024-01-14 19:15:16,750 PIL.Image    DEBUG    Importing PpmImagePlugin
2024-01-14 19:15:16,750 PIL.Image    DEBUG    Importing PsdImagePlugin
2024-01-14 19:15:16,750 PIL.Image    DEBUG    Importing QoiImagePlugin
2024-01-14 19:15:16,750 PIL.Image    DEBUG    Importing SgiImagePlugin
2024-01-14 19:15:16,750 PIL.Image    DEBUG    Importing SpiderImagePlugin
2024-01-14 19:15:16,750 PIL.Image    DEBUG    Importing SunImagePlugin
2024-01-14 19:15:16,750 PIL.Image    DEBUG    Importing TgaImagePlugin
2024-01-14 19:15:16,750 PIL.Image    DEBUG    Importing TiffImagePlugin
2024-01-14 19:15:16,750 PIL.Image    DEBUG    Importing WebPImagePlugin
2024-01-14 19:15:16,750 PIL.Image    DEBUG    Importing WmfImagePlugin
2024-01-14 19:15:16,750 PIL.Image    DEBUG    Importing XbmImagePlugin
2024-01-14 19:15:16,766 PIL.Image    DEBUG    Importing XpmImagePlugin
2024-01-14 19:15:16,766 PIL.Image    DEBUG    Importing XVThumbImagePlugin
2024-01-14 19:21:10,390 django.request WARNING  Not Found: /user/
2024-01-14 19:21:18,013 django.request WARNING  Not Found: /user/registrations
2024-01-14 19:21:27,205 django.request WARNING  Not Found: /api/user/registrations
2024-01-14 19:21:58,358 django.request WARNING  Not Found: /api/user/register
2024-01-14 19:22:09,759 django.request WARNING  Method Not Allowed: /api/users/register/
2024-01-14 19:25:50,543 django.request WARNING  Bad Request: /api/users/register/
2024-01-14 19:26:36,535 django.request WARNING  Not Found: /api/register
2024-01-14 19:26:42,144 django.request WARNING  Method Not Allowed: /api/users/register/
2024-01-14 19:26:56,384 django.request WARNING  Not Found: /api/register
2024-01-14 19:27:01,206 django.request WARNING  Not Found: /api/register
2024-01-14 19:27:04,973 django.request WARNING  Not Found: /api/register
2024-01-14 19:27:06,488 django.request WARNING  Method Not Allowed: /api/users/register/
2024-01-14 19:27:07,042 django.request WARNING  Method Not Allowed: /api/users/register/
2024-01-14 19:27:07,201 django.request WARNING  Method Not Allowed: /api/users/register/
2024-01-14 19:28:28,174 django.request WARNING  Bad Request: /api/users/register/
2024-01-14 19:29:14,725 django.request WARNING  Bad Request: /api/users/register/
2024-01-14 19:29:28,617 django.request WARNING  Method Not Allowed: /api/users/register/
2024-01-14 19:29:30,367 django.request WARNING  Method Not Allowed: /api/users/register/
2024-01-14 19:29:31,509 django.request WARNING  Method Not Allowed: /api/users/register/
2024-01-14 19:29:31,686 django.request WARNING  Method Not Allowed: /api/users/register/
2024-01-14 19:30:00,403 django.request WARNING  Method Not Allowed: /api/users/register/
2024-01-14 19:30:01,198 django.request WARNING  Method Not Allowed: /api/users/register/
2024-01-14 19:30:01,378 django.request WARNING  Method Not Allowed: /api/users/register/
2024-01-16 14:42:02,821 django.utils.autoreload INFO     Watching for file changes with StatReloader
2024-01-16 14:42:08,134 django.request WARNING  Not Found: /
2024-01-16 14:42:08,243 django.request WARNING  Not Found: /favicon.ico
2024-01-16 14:44:36,808 django.utils.autoreload INFO     Watching for file changes with StatReloader
2024-01-16 14:44:41,496 django.request WARNING  Not Found: /
2024-01-16 14:50:04,292 PIL.Image    DEBUG    Importing BlpImagePlugin
2024-01-16 14:50:04,292 PIL.Image    DEBUG    Importing BmpImagePlugin
2024-01-16 14:50:04,292 PIL.Image    DEBUG    Importing BufrStubImagePlugin
2024-01-16 14:50:04,307 PIL.Image    DEBUG    Importing CurImagePlugin
2024-01-16 14:50:04,309 PIL.Image    DEBUG    Importing DcxImagePlugin
2024-01-16 14:50:04,309 PIL.Image    DEBUG    Importing DdsImagePlugin
2024-01-16 14:50:04,309 PIL.Image    DEBUG    Importing EpsImagePlugin
2024-01-16 14:50:04,309 PIL.Image    DEBUG    Importing FitsImagePlugin
2024-01-16 14:50:04,326 PIL.Image    DEBUG    Importing FliImagePlugin
2024-01-16 14:50:04,326 PIL.Image    DEBUG    Importing FpxImagePlugin
2024-01-16 14:50:04,326 PIL.Image    DEBUG    Image: failed to import FpxImagePlugin: No module named 'olefile'
2024-01-16 14:50:04,326 PIL.Image    DEBUG    Importing FtexImagePlugin
2024-01-16 14:50:04,326 PIL.Image    DEBUG    Importing GbrImagePlugin
2024-01-16 14:50:04,326 PIL.Image    DEBUG    Importing GifImagePlugin
2024-01-16 14:50:04,326 PIL.Image    DEBUG    Importing GribStubImagePlugin
2024-01-16 14:50:04,326 PIL.Image    DEBUG    Importing Hdf5StubImagePlugin
2024-01-16 14:50:04,326 PIL.Image    DEBUG    Importing IcnsImagePlugin
2024-01-16 14:50:04,342 PIL.Image    DEBUG    Importing IcoImagePlugin
2024-01-16 14:50:04,342 PIL.Image    DEBUG    Importing ImImagePlugin
2024-01-16 14:50:04,342 PIL.Image    DEBUG    Importing ImtImagePlugin
2024-01-16 14:50:04,342 PIL.Image    DEBUG    Importing IptcImagePlugin
2024-01-16 14:50:04,342 PIL.Image    DEBUG    Importing JpegImagePlugin
2024-01-16 14:50:04,342 PIL.Image    DEBUG    Importing Jpeg2KImagePlugin
2024-01-16 14:50:04,342 PIL.Image    DEBUG    Importing McIdasImagePlugin
2024-01-16 14:50:04,342 PIL.Image    DEBUG    Importing MicImagePlugin
2024-01-16 14:50:04,359 PIL.Image    DEBUG    Image: failed to import MicImagePlugin: No module named 'olefile'
2024-01-16 14:50:04,359 PIL.Image    DEBUG    Importing MpegImagePlugin
2024-01-16 14:50:04,359 PIL.Image    DEBUG    Importing MpoImagePlugin
2024-01-16 14:50:04,359 PIL.Image    DEBUG    Importing MspImagePlugin
2024-01-16 14:50:04,373 PIL.Image    DEBUG    Importing PalmImagePlugin
2024-01-16 14:50:04,376 PIL.Image    DEBUG    Importing PcdImagePlugin
2024-01-16 14:50:04,376 PIL.Image    DEBUG    Importing PcxImagePlugin
2024-01-16 14:50:04,376 PIL.Image    DEBUG    Importing PdfImagePlugin
2024-01-16 14:50:04,392 PIL.Image    DEBUG    Importing PixarImagePlugin
2024-01-16 14:50:04,392 PIL.Image    DEBUG    Importing PngImagePlugin
2024-01-16 14:50:04,392 PIL.Image    DEBUG    Importing PpmImagePlugin
2024-01-16 14:50:04,392 PIL.Image    DEBUG    Importing PsdImagePlugin
2024-01-16 14:50:04,392 PIL.Image    DEBUG    Importing QoiImagePlugin
2024-01-16 14:50:04,392 PIL.Image    DEBUG    Importing SgiImagePlugin
2024-01-16 14:50:04,392 PIL.Image    DEBUG    Importing SpiderImagePlugin
2024-01-16 14:50:04,392 PIL.Image    DEBUG    Importing SunImagePlugin
2024-01-16 14:50:04,409 PIL.Image    DEBUG    Importing TgaImagePlugin
2024-01-16 14:50:04,409 PIL.Image    DEBUG    Importing TiffImagePlugin
2024-01-16 14:50:04,409 PIL.Image    DEBUG    Importing WebPImagePlugin
2024-01-16 14:50:04,409 PIL.Image    DEBUG    Importing WmfImagePlugin
2024-01-16 14:50:04,409 PIL.Image    DEBUG    Importing XbmImagePlugin
2024-01-16 14:50:04,409 PIL.Image    DEBUG    Importing XpmImagePlugin
2024-01-16 14:50:04,425 PIL.Image    DEBUG    Importing XVThumbImagePlugin
2024-01-17 12:49:32,399 django.utils.autoreload INFO     Watching for file changes with StatReloader
2024-01-17 12:49:34,073 django.request WARNING  Not Found: /
2024-01-17 12:49:34,144 django.request WARNING  Not Found: /favicon.ico
2024-01-17 14:49:17,019 django.utils.autoreload INFO     Watching for file changes with StatReloader
2024-01-17 14:49:19,752 django.request WARNING  Not Found: /
2024-01-17 14:52:41,426 PIL.Image    DEBUG    Importing BlpImagePlugin
2024-01-17 14:52:41,426 PIL.Image    DEBUG    Importing BmpImagePlugin
2024-01-17 14:52:41,426 PIL.Image    DEBUG    Importing BufrStubImagePlugin
2024-01-17 14:52:41,426 PIL.Image    DEBUG    Importing CurImagePlugin
2024-01-17 14:52:41,440 PIL.Image    DEBUG    Importing DcxImagePlugin
2024-01-17 14:52:41,443 PIL.Image    DEBUG    Importing DdsImagePlugin
2024-01-17 14:52:41,443 PIL.Image    DEBUG    Importing EpsImagePlugin
2024-01-17 14:52:41,443 PIL.Image    DEBUG    Importing FitsImagePlugin
2024-01-17 14:52:41,443 PIL.Image    DEBUG    Importing FliImagePlugin
2024-01-17 14:52:41,460 PIL.Image    DEBUG    Importing FpxImagePlugin
2024-01-17 14:52:41,460 PIL.Image    DEBUG    Image: failed to import FpxImagePlugin: No module named 'olefile'
2024-01-17 14:52:41,460 PIL.Image    DEBUG    Importing FtexImagePlugin
2024-01-17 14:52:41,460 PIL.Image    DEBUG    Importing GbrImagePlugin
2024-01-17 14:52:41,460 PIL.Image    DEBUG    Importing GifImagePlugin
2024-01-17 14:52:41,460 PIL.Image    DEBUG    Importing GribStubImagePlugin
2024-01-17 14:52:41,460 PIL.Image    DEBUG    Importing Hdf5StubImagePlugin
2024-01-17 14:52:41,473 PIL.Image    DEBUG    Importing IcnsImagePlugin
2024-01-17 14:52:41,476 PIL.Image    DEBUG    Importing IcoImagePlugin
2024-01-17 14:52:41,476 PIL.Image    DEBUG    Importing ImImagePlugin
2024-01-17 14:52:41,491 PIL.Image    DEBUG    Importing ImtImagePlugin
2024-01-17 14:52:41,493 PIL.Image    DEBUG    Importing IptcImagePlugin
2024-01-17 14:52:41,493 PIL.Image    DEBUG    Importing JpegImagePlugin
2024-01-17 14:52:41,493 PIL.Image    DEBUG    Importing Jpeg2KImagePlugin
2024-01-17 14:52:41,493 PIL.Image    DEBUG    Importing McIdasImagePlugin
2024-01-17 14:52:41,493 PIL.Image    DEBUG    Importing MicImagePlugin
2024-01-17 14:52:41,493 PIL.Image    DEBUG    Image: failed to import MicImagePlugin: No module named 'olefile'
2024-01-17 14:52:41,493 PIL.Image    DEBUG    Importing MpegImagePlugin
2024-01-17 14:52:41,510 PIL.Image    DEBUG    Importing MpoImagePlugin
2024-01-17 14:52:41,510 PIL.Image    DEBUG    Importing MspImagePlugin
2024-01-17 14:52:41,526 PIL.Image    DEBUG    Importing PalmImagePlugin
2024-01-17 14:52:41,526 PIL.Image    DEBUG    Importing PcdImagePlugin
2024-01-17 14:52:41,526 PIL.Image    DEBUG    Importing PcxImagePlugin
2024-01-17 14:52:41,526 PIL.Image    DEBUG    Importing PdfImagePlugin
2024-01-17 14:52:41,543 PIL.Image    DEBUG    Importing PixarImagePlugin
2024-01-17 14:52:41,543 PIL.Image    DEBUG    Importing PngImagePlugin
2024-01-17 14:52:41,543 PIL.Image    DEBUG    Importing PpmImagePlugin
2024-01-17 14:52:41,543 PIL.Image    DEBUG    Importing PsdImagePlugin
2024-01-17 14:52:41,560 PIL.Image    DEBUG    Importing QoiImagePlugin
2024-01-17 14:52:41,560 PIL.Image    DEBUG    Importing SgiImagePlugin
2024-01-17 14:52:41,560 PIL.Image    DEBUG    Importing SpiderImagePlugin
2024-01-17 14:52:41,560 PIL.Image    DEBUG    Importing SunImagePlugin
2024-01-17 14:52:41,560 PIL.Image    DEBUG    Importing TgaImagePlugin
2024-01-17 14:52:41,560 PIL.Image    DEBUG    Importing TiffImagePlugin
2024-01-17 14:52:41,560 PIL.Image    DEBUG    Importing WebPImagePlugin
2024-01-17 14:52:41,576 PIL.Image    DEBUG    Importing WmfImagePlugin
2024-01-17 14:52:41,576 PIL.Image    DEBUG    Importing XbmImagePlugin
2024-01-17 14:52:41,576 PIL.Image    DEBUG    Importing XpmImagePlugin
2024-01-17 14:52:41,590 PIL.Image    DEBUG    Importing XVThumbImagePlugin
2024-01-17 14:53:00,645 django.utils.autoreload INFO     Watching for file changes with StatReloader
2024-01-17 14:53:05,508 django.request WARNING  Not Found: /
2024-01-18 14:18:48,100 django.utils.autoreload INFO     Watching for file changes with StatReloader
2024-01-18 14:18:50,151 django.request WARNING  Not Found: /
2024-01-18 14:18:50,215 django.request WARNING  Not Found: /favicon.ico
2024-01-18 14:18:52,335 django.request WARNING  Not Found: /women/home/
2024-01-18 16:19:56,853 django.utils.autoreload INFO     Watching for file changes with StatReloader
2024-01-18 16:19:58,816 django.request WARNING  Not Found: /
2024-01-18 16:20:15,157 django.request WARNING  Not Found: /women/home/
2024-01-18 16:23:55,700 django.request WARNING  Not Found: /users/
2024-01-18 16:25:42,495 django.request WARNING  Not Found: /api/users/
2024-01-18 16:25:48,009 django.request WARNING  Method Not Allowed: /api/users/login/
2024-01-18 16:26:37,932 django.request WARNING  Bad Request: /api/users/login/
2024-01-18 16:27:03,234 django.request WARNING  Not Found: /users/login
2024-01-18 16:28:41,830 django.request WARNING  Method Not Allowed: /api/users/login/
2024-01-18 16:29:20,816 django.request WARNING  Bad Request: /api/users/login/
2024-01-18 16:30:16,854 django.request WARNING  Bad Request: /api/users/login/
2024-01-18 16:31:03,593 django.request ERROR    Internal Server Error: /api/users/login/
Traceback (most recent call last):
  File "C:\Users\Nick\AppData\Local\Programs\Python\Python310\lib\site-packages\django\core\handlers\exception.py", line 55, in inner
    response = get_response(request)
  File "C:\Users\Nick\AppData\Local\Programs\Python\Python310\lib\site-packages\django\core\handlers\base.py", line 197, in _get_response
    response = wrapped_callback(request, *callback_args, **callback_kwargs)
  File "C:\Users\Nick\AppData\Local\Programs\Python\Python310\lib\site-packages\django\views\decorators\csrf.py", line 56, in wrapper_view
    return view_func(*args, **kwargs)
  File "C:\Users\Nick\AppData\Local\Programs\Python\Python310\lib\site-packages\django\views\generic\base.py", line 104, in view
    return self.dispatch(request, *args, **kwargs)
  File "C:\Users\Nick\AppData\Local\Programs\Python\Python310\lib\site-packages\rest_framework\views.py", line 509, in dispatch
    response = self.handle_exception(exc)
  File "C:\Users\Nick\AppData\Local\Programs\Python\Python310\lib\site-packages\rest_framework\views.py", line 469, in handle_exception
    self.raise_uncaught_exception(exc)
  File "C:\Users\Nick\AppData\Local\Programs\Python\Python310\lib\site-packages\rest_framework\views.py", line 480, in raise_uncaught_exception
    raise exc
  File "C:\Users\Nick\AppData\Local\Programs\Python\Python310\lib\site-packages\rest_framework\views.py", line 506, in dispatch
    response = handler(request, *args, **kwargs)
  File "C:\Users\Nick\Desktop\git\Advert-Project\mytestprj\advert\authentication\views.py", line 33, in post
    email = request.data['email']
KeyError: 'email'
2024-01-18 16:33:15,958 django.request WARNING  Method Not Allowed: /api/users/login/
2024-01-18 16:33:51,644 django.request WARNING  Not Found: /api/
2024-01-18 16:33:58,446 django.request ERROR    Internal Server Error: /api/content/adverts/
Traceback (most recent call last):
  File "C:\Users\Nick\AppData\Local\Programs\Python\Python310\lib\site-packages\django\core\handlers\exception.py", line 55, in inner
    response = get_response(request)
  File "C:\Users\Nick\AppData\Local\Programs\Python\Python310\lib\site-packages\django\core\handlers\base.py", line 197, in _get_response
    response = wrapped_callback(request, *callback_args, **callback_kwargs)
  File "C:\Users\Nick\AppData\Local\Programs\Python\Python310\lib\site-packages\django\views\decorators\csrf.py", line 56, in wrapper_view
    return view_func(*args, **kwargs)
  File "C:\Users\Nick\AppData\Local\Programs\Python\Python310\lib\site-packages\django\views\generic\base.py", line 104, in view
    return self.dispatch(request, *args, **kwargs)
  File "C:\Users\Nick\AppData\Local\Programs\Python\Python310\lib\site-packages\rest_framework\views.py", line 509, in dispatch
    response = self.handle_exception(exc)
  File "C:\Users\Nick\AppData\Local\Programs\Python\Python310\lib\site-packages\rest_framework\views.py", line 469, in handle_exception
    self.raise_uncaught_exception(exc)
  File "C:\Users\Nick\AppData\Local\Programs\Python\Python310\lib\site-packages\rest_framework\views.py", line 480, in raise_uncaught_exception
    raise exc
  File "C:\Users\Nick\AppData\Local\Programs\Python\Python310\lib\site-packages\rest_framework\views.py", line 506, in dispatch
    response = handler(request, *args, **kwargs)
  File "C:\Users\Nick\Desktop\git\Advert-Project\mytestprj\advert\api\views.py", line 131, in get
    "adverts": serializer.data
  File "C:\Users\Nick\AppData\Local\Programs\Python\Python310\lib\site-packages\rest_framework\serializers.py", line 768, in data
    ret = super().data
  File "C:\Users\Nick\AppData\Local\Programs\Python\Python310\lib\site-packages\rest_framework\serializers.py", line 253, in data
    self._data = self.to_representation(self.instance)
  File "C:\Users\Nick\AppData\Local\Programs\Python\Python310\lib\site-packages\rest_framework\serializers.py", line 686, in to_representation
    return [
  File "C:\Users\Nick\AppData\Local\Programs\Python\Python310\lib\site-packages\rest_framework\serializers.py", line 687, in <listcomp>
    self.child.to_representation(item) for item in iterable
  File "C:\Users\Nick\AppData\Local\Programs\Python\Python310\lib\site-packages\rest_framework\serializers.py", line 507, in to_representation
    for field in fields:
  File "C:\Users\Nick\AppData\Local\Programs\Python\Python310\lib\site-packages\rest_framework\serializers.py", line 368, in _readable_fields
    for field in self.fields.values():
  File "C:\Users\Nick\AppData\Local\Programs\Python\Python310\lib\site-packages\django\utils\functional.py", line 57, in __get__
    res = instance.__dict__[self.name] = self.func(instance)
  File "C:\Users\Nick\AppData\Local\Programs\Python\Python310\lib\site-packages\rest_framework\serializers.py", line 356, in fields
    for key, value in self.get_fields().items():
  File "C:\Users\Nick\AppData\Local\Programs\Python\Python310\lib\site-packages\rest_framework\serializers.py", line 1076, in get_fields
    field_class, field_kwargs = self.build_field(
  File "C:\Users\Nick\AppData\Local\Programs\Python\Python310\lib\site-packages\rest_framework\serializers.py", line 1222, in build_field
    return self.build_unknown_field(field_name, model_class)
  File "C:\Users\Nick\AppData\Local\Programs\Python\Python310\lib\site-packages\rest_framework\serializers.py", line 1340, in build_unknown_field
    raise ImproperlyConfigured(
django.core.exceptions.ImproperlyConfigured: Field name `category` is not valid for model `Advert`.
2024-01-18 16:34:04,166 django.request WARNING  Not Found: /api/content
2024-01-18 16:34:12,277 django.request WARNING  Not Found: /api/content/
2024-01-18 16:34:17,564 django.request ERROR    Internal Server Error: /api/content/adverts/
Traceback (most recent call last):
  File "C:\Users\Nick\AppData\Local\Programs\Python\Python310\lib\site-packages\django\core\handlers\exception.py", line 55, in inner
    response = get_response(request)
  File "C:\Users\Nick\AppData\Local\Programs\Python\Python310\lib\site-packages\django\core\handlers\base.py", line 197, in _get_response
    response = wrapped_callback(request, *callback_args, **callback_kwargs)
  File "C:\Users\Nick\AppData\Local\Programs\Python\Python310\lib\site-packages\django\views\decorators\csrf.py", line 56, in wrapper_view
    return view_func(*args, **kwargs)
  File "C:\Users\Nick\AppData\Local\Programs\Python\Python310\lib\site-packages\django\views\generic\base.py", line 104, in view
    return self.dispatch(request, *args, **kwargs)
  File "C:\Users\Nick\AppData\Local\Programs\Python\Python310\lib\site-packages\rest_framework\views.py", line 509, in dispatch
    response = self.handle_exception(exc)
  File "C:\Users\Nick\AppData\Local\Programs\Python\Python310\lib\site-packages\rest_framework\views.py", line 469, in handle_exception
    self.raise_uncaught_exception(exc)
  File "C:\Users\Nick\AppData\Local\Programs\Python\Python310\lib\site-packages\rest_framework\views.py", line 480, in raise_uncaught_exception
    raise exc
  File "C:\Users\Nick\AppData\Local\Programs\Python\Python310\lib\site-packages\rest_framework\views.py", line 506, in dispatch
    response = handler(request, *args, **kwargs)
  File "C:\Users\Nick\Desktop\git\Advert-Project\mytestprj\advert\api\views.py", line 131, in get
    "adverts": serializer.data
  File "C:\Users\Nick\AppData\Local\Programs\Python\Python310\lib\site-packages\rest_framework\serializers.py", line 768, in data
    ret = super().data
  File "C:\Users\Nick\AppData\Local\Programs\Python\Python310\lib\site-packages\rest_framework\serializers.py", line 253, in data
    self._data = self.to_representation(self.instance)
  File "C:\Users\Nick\AppData\Local\Programs\Python\Python310\lib\site-packages\rest_framework\serializers.py", line 686, in to_representation
    return [
  File "C:\Users\Nick\AppData\Local\Programs\Python\Python310\lib\site-packages\rest_framework\serializers.py", line 687, in <listcomp>
    self.child.to_representation(item) for item in iterable
  File "C:\Users\Nick\AppData\Local\Programs\Python\Python310\lib\site-packages\rest_framework\serializers.py", line 507, in to_representation
    for field in fields:
  File "C:\Users\Nick\AppData\Local\Programs\Python\Python310\lib\site-packages\rest_framework\serializers.py", line 368, in _readable_fields
    for field in self.fields.values():
  File "C:\Users\Nick\AppData\Local\Programs\Python\Python310\lib\site-packages\django\utils\functional.py", line 57, in __get__
    res = instance.__dict__[self.name] = self.func(instance)
  File "C:\Users\Nick\AppData\Local\Programs\Python\Python310\lib\site-packages\rest_framework\serializers.py", line 356, in fields
    for key, value in self.get_fields().items():
  File "C:\Users\Nick\AppData\Local\Programs\Python\Python310\lib\site-packages\rest_framework\serializers.py", line 1076, in get_fields
    field_class, field_kwargs = self.build_field(
  File "C:\Users\Nick\AppData\Local\Programs\Python\Python310\lib\site-packages\rest_framework\serializers.py", line 1222, in build_field
    return self.build_unknown_field(field_name, model_class)
  File "C:\Users\Nick\AppData\Local\Programs\Python\Python310\lib\site-packages\rest_framework\serializers.py", line 1340, in build_unknown_field
    raise ImproperlyConfigured(
django.core.exceptions.ImproperlyConfigured: Field name `category` is not valid for model `Advert`.
2024-01-18 16:37:14,008 django.utils.autoreload INFO     C:\Users\Nick\Desktop\git\Advert-Project\mytestprj\advert\api\views.py changed, reloading.
2024-01-18 16:37:15,150 django.utils.autoreload INFO     Watching for file changes with StatReloader
2024-01-18 16:37:16,097 django.request ERROR    Internal Server Error: /api/content/adverts/
Traceback (most recent call last):
  File "C:\Users\Nick\AppData\Local\Programs\Python\Python310\lib\site-packages\django\core\handlers\exception.py", line 55, in inner
    response = get_response(request)
  File "C:\Users\Nick\AppData\Local\Programs\Python\Python310\lib\site-packages\django\core\handlers\base.py", line 197, in _get_response
    response = wrapped_callback(request, *callback_args, **callback_kwargs)
  File "C:\Users\Nick\AppData\Local\Programs\Python\Python310\lib\site-packages\django\views\decorators\csrf.py", line 56, in wrapper_view
    return view_func(*args, **kwargs)
  File "C:\Users\Nick\AppData\Local\Programs\Python\Python310\lib\site-packages\django\views\generic\base.py", line 104, in view
    return self.dispatch(request, *args, **kwargs)
  File "C:\Users\Nick\AppData\Local\Programs\Python\Python310\lib\site-packages\rest_framework\views.py", line 509, in dispatch
    response = self.handle_exception(exc)
  File "C:\Users\Nick\AppData\Local\Programs\Python\Python310\lib\site-packages\rest_framework\views.py", line 469, in handle_exception
    self.raise_uncaught_exception(exc)
  File "C:\Users\Nick\AppData\Local\Programs\Python\Python310\lib\site-packages\rest_framework\views.py", line 480, in raise_uncaught_exception
    raise exc
  File "C:\Users\Nick\AppData\Local\Programs\Python\Python310\lib\site-packages\rest_framework\views.py", line 506, in dispatch
    response = handler(request, *args, **kwargs)
  File "C:\Users\Nick\Desktop\git\Advert-Project\mytestprj\advert\api\views.py", line 131, in get
    "adverts": serializer.data
  File "C:\Users\Nick\AppData\Local\Programs\Python\Python310\lib\site-packages\rest_framework\serializers.py", line 768, in data
    ret = super().data
  File "C:\Users\Nick\AppData\Local\Programs\Python\Python310\lib\site-packages\rest_framework\serializers.py", line 253, in data
    self._data = self.to_representation(self.instance)
  File "C:\Users\Nick\AppData\Local\Programs\Python\Python310\lib\site-packages\rest_framework\serializers.py", line 686, in to_representation
    return [
  File "C:\Users\Nick\AppData\Local\Programs\Python\Python310\lib\site-packages\rest_framework\serializers.py", line 687, in <listcomp>
    self.child.to_representation(item) for item in iterable
  File "C:\Users\Nick\AppData\Local\Programs\Python\Python310\lib\site-packages\rest_framework\serializers.py", line 507, in to_representation
    for field in fields:
  File "C:\Users\Nick\AppData\Local\Programs\Python\Python310\lib\site-packages\rest_framework\serializers.py", line 368, in _readable_fields
    for field in self.fields.values():
  File "C:\Users\Nick\AppData\Local\Programs\Python\Python310\lib\site-packages\django\utils\functional.py", line 57, in __get__
    res = instance.__dict__[self.name] = self.func(instance)
  File "C:\Users\Nick\AppData\Local\Programs\Python\Python310\lib\site-packages\rest_framework\serializers.py", line 356, in fields
    for key, value in self.get_fields().items():
  File "C:\Users\Nick\AppData\Local\Programs\Python\Python310\lib\site-packages\rest_framework\serializers.py", line 1076, in get_fields
    field_class, field_kwargs = self.build_field(
  File "C:\Users\Nick\AppData\Local\Programs\Python\Python310\lib\site-packages\rest_framework\serializers.py", line 1222, in build_field
    return self.build_unknown_field(field_name, model_class)
  File "C:\Users\Nick\AppData\Local\Programs\Python\Python310\lib\site-packages\rest_framework\serializers.py", line 1340, in build_unknown_field
    raise ImproperlyConfigured(
django.core.exceptions.ImproperlyConfigured: Field name `category` is not valid for model `Advert`.
2024-01-18 16:37:21,170 django.request ERROR    Internal Server Error: /api/content/adverts/
Traceback (most recent call last):
  File "C:\Users\Nick\AppData\Local\Programs\Python\Python310\lib\site-packages\django\core\handlers\exception.py", line 55, in inner
    response = get_response(request)
  File "C:\Users\Nick\AppData\Local\Programs\Python\Python310\lib\site-packages\django\core\handlers\base.py", line 197, in _get_response
    response = wrapped_callback(request, *callback_args, **callback_kwargs)
  File "C:\Users\Nick\AppData\Local\Programs\Python\Python310\lib\site-packages\django\views\decorators\csrf.py", line 56, in wrapper_view
    return view_func(*args, **kwargs)
  File "C:\Users\Nick\AppData\Local\Programs\Python\Python310\lib\site-packages\django\views\generic\base.py", line 104, in view
    return self.dispatch(request, *args, **kwargs)
  File "C:\Users\Nick\AppData\Local\Programs\Python\Python310\lib\site-packages\rest_framework\views.py", line 509, in dispatch
    response = self.handle_exception(exc)
  File "C:\Users\Nick\AppData\Local\Programs\Python\Python310\lib\site-packages\rest_framework\views.py", line 469, in handle_exception
    self.raise_uncaught_exception(exc)
  File "C:\Users\Nick\AppData\Local\Programs\Python\Python310\lib\site-packages\rest_framework\views.py", line 480, in raise_uncaught_exception
    raise exc
  File "C:\Users\Nick\AppData\Local\Programs\Python\Python310\lib\site-packages\rest_framework\views.py", line 506, in dispatch
    response = handler(request, *args, **kwargs)
  File "C:\Users\Nick\Desktop\git\Advert-Project\mytestprj\advert\api\views.py", line 131, in get
    "adverts": serializer.data
  File "C:\Users\Nick\AppData\Local\Programs\Python\Python310\lib\site-packages\rest_framework\serializers.py", line 768, in data
    ret = super().data
  File "C:\Users\Nick\AppData\Local\Programs\Python\Python310\lib\site-packages\rest_framework\serializers.py", line 253, in data
    self._data = self.to_representation(self.instance)
  File "C:\Users\Nick\AppData\Local\Programs\Python\Python310\lib\site-packages\rest_framework\serializers.py", line 686, in to_representation
    return [
  File "C:\Users\Nick\AppData\Local\Programs\Python\Python310\lib\site-packages\rest_framework\serializers.py", line 687, in <listcomp>
    self.child.to_representation(item) for item in iterable
  File "C:\Users\Nick\AppData\Local\Programs\Python\Python310\lib\site-packages\rest_framework\serializers.py", line 507, in to_representation
    for field in fields:
  File "C:\Users\Nick\AppData\Local\Programs\Python\Python310\lib\site-packages\rest_framework\serializers.py", line 368, in _readable_fields
    for field in self.fields.values():
  File "C:\Users\Nick\AppData\Local\Programs\Python\Python310\lib\site-packages\django\utils\functional.py", line 57, in __get__
    res = instance.__dict__[self.name] = self.func(instance)
  File "C:\Users\Nick\AppData\Local\Programs\Python\Python310\lib\site-packages\rest_framework\serializers.py", line 356, in fields
    for key, value in self.get_fields().items():
  File "C:\Users\Nick\AppData\Local\Programs\Python\Python310\lib\site-packages\rest_framework\serializers.py", line 1076, in get_fields
    field_class, field_kwargs = self.build_field(
  File "C:\Users\Nick\AppData\Local\Programs\Python\Python310\lib\site-packages\rest_framework\serializers.py", line 1222, in build_field
    return self.build_unknown_field(field_name, model_class)
  File "C:\Users\Nick\AppData\Local\Programs\Python\Python310\lib\site-packages\rest_framework\serializers.py", line 1340, in build_unknown_field
    raise ImproperlyConfigured(
django.core.exceptions.ImproperlyConfigured: Field name `category` is not valid for model `Advert`.
2024-01-18 16:37:21,318 django.request WARNING  Not Found: /favicon.ico
2024-01-18 16:37:25,200 django.request ERROR    Internal Server Error: /api/content/adverts/
Traceback (most recent call last):
  File "C:\Users\Nick\AppData\Local\Programs\Python\Python310\lib\site-packages\django\core\handlers\exception.py", line 55, in inner
    response = get_response(request)
  File "C:\Users\Nick\AppData\Local\Programs\Python\Python310\lib\site-packages\django\core\handlers\base.py", line 197, in _get_response
    response = wrapped_callback(request, *callback_args, **callback_kwargs)
  File "C:\Users\Nick\AppData\Local\Programs\Python\Python310\lib\site-packages\django\views\decorators\csrf.py", line 56, in wrapper_view
    return view_func(*args, **kwargs)
  File "C:\Users\Nick\AppData\Local\Programs\Python\Python310\lib\site-packages\django\views\generic\base.py", line 104, in view
    return self.dispatch(request, *args, **kwargs)
  File "C:\Users\Nick\AppData\Local\Programs\Python\Python310\lib\site-packages\rest_framework\views.py", line 509, in dispatch
    response = self.handle_exception(exc)
  File "C:\Users\Nick\AppData\Local\Programs\Python\Python310\lib\site-packages\rest_framework\views.py", line 469, in handle_exception
    self.raise_uncaught_exception(exc)
  File "C:\Users\Nick\AppData\Local\Programs\Python\Python310\lib\site-packages\rest_framework\views.py", line 480, in raise_uncaught_exception
    raise exc
  File "C:\Users\Nick\AppData\Local\Programs\Python\Python310\lib\site-packages\rest_framework\views.py", line 506, in dispatch
    response = handler(request, *args, **kwargs)
  File "C:\Users\Nick\Desktop\git\Advert-Project\mytestprj\advert\api\views.py", line 131, in get
    "adverts": serializer.data
  File "C:\Users\Nick\AppData\Local\Programs\Python\Python310\lib\site-packages\rest_framework\serializers.py", line 768, in data
    ret = super().data
  File "C:\Users\Nick\AppData\Local\Programs\Python\Python310\lib\site-packages\rest_framework\serializers.py", line 253, in data
    self._data = self.to_representation(self.instance)
  File "C:\Users\Nick\AppData\Local\Programs\Python\Python310\lib\site-packages\rest_framework\serializers.py", line 686, in to_representation
    return [
  File "C:\Users\Nick\AppData\Local\Programs\Python\Python310\lib\site-packages\rest_framework\serializers.py", line 687, in <listcomp>
    self.child.to_representation(item) for item in iterable
  File "C:\Users\Nick\AppData\Local\Programs\Python\Python310\lib\site-packages\rest_framework\serializers.py", line 507, in to_representation
    for field in fields:
  File "C:\Users\Nick\AppData\Local\Programs\Python\Python310\lib\site-packages\rest_framework\serializers.py", line 368, in _readable_fields
    for field in self.fields.values():
  File "C:\Users\Nick\AppData\Local\Programs\Python\Python310\lib\site-packages\django\utils\functional.py", line 57, in __get__
    res = instance.__dict__[self.name] = self.func(instance)
  File "C:\Users\Nick\AppData\Local\Programs\Python\Python310\lib\site-packages\rest_framework\serializers.py", line 356, in fields
    for key, value in self.get_fields().items():
  File "C:\Users\Nick\AppData\Local\Programs\Python\Python310\lib\site-packages\rest_framework\serializers.py", line 1076, in get_fields
    field_class, field_kwargs = self.build_field(
  File "C:\Users\Nick\AppData\Local\Programs\Python\Python310\lib\site-packages\rest_framework\serializers.py", line 1222, in build_field
    return self.build_unknown_field(field_name, model_class)
  File "C:\Users\Nick\AppData\Local\Programs\Python\Python310\lib\site-packages\rest_framework\serializers.py", line 1340, in build_unknown_field
    raise ImproperlyConfigured(
django.core.exceptions.ImproperlyConfigured: Field name `category` is not valid for model `Advert`.
2024-01-18 16:40:15,116 django.utils.autoreload INFO     C:\Users\Nick\Desktop\git\Advert-Project\mytestprj\advert\api\views.py changed, reloading.
2024-01-18 16:40:16,102 django.utils.autoreload INFO     Watching for file changes with StatReloader
2024-01-18 16:40:17,072 django.request ERROR    Internal Server Error: /api/content/adverts/
Traceback (most recent call last):
  File "C:\Users\Nick\AppData\Local\Programs\Python\Python310\lib\site-packages\django\core\handlers\exception.py", line 55, in inner
    response = get_response(request)
  File "C:\Users\Nick\AppData\Local\Programs\Python\Python310\lib\site-packages\django\core\handlers\base.py", line 197, in _get_response
    response = wrapped_callback(request, *callback_args, **callback_kwargs)
  File "C:\Users\Nick\AppData\Local\Programs\Python\Python310\lib\site-packages\django\views\decorators\csrf.py", line 56, in wrapper_view
    return view_func(*args, **kwargs)
  File "C:\Users\Nick\AppData\Local\Programs\Python\Python310\lib\site-packages\django\views\generic\base.py", line 104, in view
    return self.dispatch(request, *args, **kwargs)
  File "C:\Users\Nick\AppData\Local\Programs\Python\Python310\lib\site-packages\rest_framework\views.py", line 509, in dispatch
    response = self.handle_exception(exc)
  File "C:\Users\Nick\AppData\Local\Programs\Python\Python310\lib\site-packages\rest_framework\views.py", line 469, in handle_exception
    self.raise_uncaught_exception(exc)
  File "C:\Users\Nick\AppData\Local\Programs\Python\Python310\lib\site-packages\rest_framework\views.py", line 480, in raise_uncaught_exception
    raise exc
  File "C:\Users\Nick\AppData\Local\Programs\Python\Python310\lib\site-packages\rest_framework\views.py", line 506, in dispatch
    response = handler(request, *args, **kwargs)
  File "C:\Users\Nick\Desktop\git\Advert-Project\mytestprj\advert\api\views.py", line 131, in get
    "adverts": serializer.data
  File "C:\Users\Nick\AppData\Local\Programs\Python\Python310\lib\site-packages\rest_framework\serializers.py", line 768, in data
    ret = super().data
  File "C:\Users\Nick\AppData\Local\Programs\Python\Python310\lib\site-packages\rest_framework\serializers.py", line 253, in data
    self._data = self.to_representation(self.instance)
  File "C:\Users\Nick\AppData\Local\Programs\Python\Python310\lib\site-packages\rest_framework\serializers.py", line 686, in to_representation
    return [
  File "C:\Users\Nick\AppData\Local\Programs\Python\Python310\lib\site-packages\rest_framework\serializers.py", line 687, in <listcomp>
    self.child.to_representation(item) for item in iterable
  File "C:\Users\Nick\AppData\Local\Programs\Python\Python310\lib\site-packages\rest_framework\serializers.py", line 507, in to_representation
    for field in fields:
  File "C:\Users\Nick\AppData\Local\Programs\Python\Python310\lib\site-packages\rest_framework\serializers.py", line 368, in _readable_fields
    for field in self.fields.values():
  File "C:\Users\Nick\AppData\Local\Programs\Python\Python310\lib\site-packages\django\utils\functional.py", line 57, in __get__
    res = instance.__dict__[self.name] = self.func(instance)
  File "C:\Users\Nick\AppData\Local\Programs\Python\Python310\lib\site-packages\rest_framework\serializers.py", line 356, in fields
    for key, value in self.get_fields().items():
  File "C:\Users\Nick\AppData\Local\Programs\Python\Python310\lib\site-packages\rest_framework\serializers.py", line 1076, in get_fields
    field_class, field_kwargs = self.build_field(
  File "C:\Users\Nick\AppData\Local\Programs\Python\Python310\lib\site-packages\rest_framework\serializers.py", line 1222, in build_field
    return self.build_unknown_field(field_name, model_class)
  File "C:\Users\Nick\AppData\Local\Programs\Python\Python310\lib\site-packages\rest_framework\serializers.py", line 1340, in build_unknown_field
    raise ImproperlyConfigured(
django.core.exceptions.ImproperlyConfigured: Field name `category` is not valid for model `Advert`.
2024-01-18 16:40:17,206 django.request WARNING  Not Found: /favicon.ico
2024-01-18 16:40:18,057 django.request ERROR    Internal Server Error: /api/content/adverts/
Traceback (most recent call last):
  File "C:\Users\Nick\AppData\Local\Programs\Python\Python310\lib\site-packages\django\core\handlers\exception.py", line 55, in inner
    response = get_response(request)
  File "C:\Users\Nick\AppData\Local\Programs\Python\Python310\lib\site-packages\django\core\handlers\base.py", line 197, in _get_response
    response = wrapped_callback(request, *callback_args, **callback_kwargs)
  File "C:\Users\Nick\AppData\Local\Programs\Python\Python310\lib\site-packages\django\views\decorators\csrf.py", line 56, in wrapper_view
    return view_func(*args, **kwargs)
  File "C:\Users\Nick\AppData\Local\Programs\Python\Python310\lib\site-packages\django\views\generic\base.py", line 104, in view
    return self.dispatch(request, *args, **kwargs)
  File "C:\Users\Nick\AppData\Local\Programs\Python\Python310\lib\site-packages\rest_framework\views.py", line 509, in dispatch
    response = self.handle_exception(exc)
  File "C:\Users\Nick\AppData\Local\Programs\Python\Python310\lib\site-packages\rest_framework\views.py", line 469, in handle_exception
    self.raise_uncaught_exception(exc)
  File "C:\Users\Nick\AppData\Local\Programs\Python\Python310\lib\site-packages\rest_framework\views.py", line 480, in raise_uncaught_exception
    raise exc
  File "C:\Users\Nick\AppData\Local\Programs\Python\Python310\lib\site-packages\rest_framework\views.py", line 506, in dispatch
    response = handler(request, *args, **kwargs)
  File "C:\Users\Nick\Desktop\git\Advert-Project\mytestprj\advert\api\views.py", line 131, in get
    "adverts": serializer.data
  File "C:\Users\Nick\AppData\Local\Programs\Python\Python310\lib\site-packages\rest_framework\serializers.py", line 768, in data
    ret = super().data
  File "C:\Users\Nick\AppData\Local\Programs\Python\Python310\lib\site-packages\rest_framework\serializers.py", line 253, in data
    self._data = self.to_representation(self.instance)
  File "C:\Users\Nick\AppData\Local\Programs\Python\Python310\lib\site-packages\rest_framework\serializers.py", line 686, in to_representation
    return [
  File "C:\Users\Nick\AppData\Local\Programs\Python\Python310\lib\site-packages\rest_framework\serializers.py", line 687, in <listcomp>
    self.child.to_representation(item) for item in iterable
  File "C:\Users\Nick\AppData\Local\Programs\Python\Python310\lib\site-packages\rest_framework\serializers.py", line 507, in to_representation
    for field in fields:
  File "C:\Users\Nick\AppData\Local\Programs\Python\Python310\lib\site-packages\rest_framework\serializers.py", line 368, in _readable_fields
    for field in self.fields.values():
  File "C:\Users\Nick\AppData\Local\Programs\Python\Python310\lib\site-packages\django\utils\functional.py", line 57, in __get__
    res = instance.__dict__[self.name] = self.func(instance)
  File "C:\Users\Nick\AppData\Local\Programs\Python\Python310\lib\site-packages\rest_framework\serializers.py", line 356, in fields
    for key, value in self.get_fields().items():
  File "C:\Users\Nick\AppData\Local\Programs\Python\Python310\lib\site-packages\rest_framework\serializers.py", line 1076, in get_fields
    field_class, field_kwargs = self.build_field(
  File "C:\Users\Nick\AppData\Local\Programs\Python\Python310\lib\site-packages\rest_framework\serializers.py", line 1222, in build_field
    return self.build_unknown_field(field_name, model_class)
  File "C:\Users\Nick\AppData\Local\Programs\Python\Python310\lib\site-packages\rest_framework\serializers.py", line 1340, in build_unknown_field
    raise ImproperlyConfigured(
django.core.exceptions.ImproperlyConfigured: Field name `category` is not valid for model `Advert`.
2024-01-18 16:40:18,246 django.request WARNING  Not Found: /favicon.ico
2024-01-18 16:40:18,989 django.request ERROR    Internal Server Error: /api/content/adverts/
Traceback (most recent call last):
  File "C:\Users\Nick\AppData\Local\Programs\Python\Python310\lib\site-packages\django\core\handlers\exception.py", line 55, in inner
    response = get_response(request)
  File "C:\Users\Nick\AppData\Local\Programs\Python\Python310\lib\site-packages\django\core\handlers\base.py", line 197, in _get_response
    response = wrapped_callback(request, *callback_args, **callback_kwargs)
  File "C:\Users\Nick\AppData\Local\Programs\Python\Python310\lib\site-packages\django\views\decorators\csrf.py", line 56, in wrapper_view
    return view_func(*args, **kwargs)
  File "C:\Users\Nick\AppData\Local\Programs\Python\Python310\lib\site-packages\django\views\generic\base.py", line 104, in view
    return self.dispatch(request, *args, **kwargs)
  File "C:\Users\Nick\AppData\Local\Programs\Python\Python310\lib\site-packages\rest_framework\views.py", line 509, in dispatch
    response = self.handle_exception(exc)
  File "C:\Users\Nick\AppData\Local\Programs\Python\Python310\lib\site-packages\rest_framework\views.py", line 469, in handle_exception
    self.raise_uncaught_exception(exc)
  File "C:\Users\Nick\AppData\Local\Programs\Python\Python310\lib\site-packages\rest_framework\views.py", line 480, in raise_uncaught_exception
    raise exc
  File "C:\Users\Nick\AppData\Local\Programs\Python\Python310\lib\site-packages\rest_framework\views.py", line 506, in dispatch
    response = handler(request, *args, **kwargs)
  File "C:\Users\Nick\Desktop\git\Advert-Project\mytestprj\advert\api\views.py", line 131, in get
    "adverts": serializer.data
  File "C:\Users\Nick\AppData\Local\Programs\Python\Python310\lib\site-packages\rest_framework\serializers.py", line 768, in data
    ret = super().data
  File "C:\Users\Nick\AppData\Local\Programs\Python\Python310\lib\site-packages\rest_framework\serializers.py", line 253, in data
    self._data = self.to_representation(self.instance)
  File "C:\Users\Nick\AppData\Local\Programs\Python\Python310\lib\site-packages\rest_framework\serializers.py", line 686, in to_representation
    return [
  File "C:\Users\Nick\AppData\Local\Programs\Python\Python310\lib\site-packages\rest_framework\serializers.py", line 687, in <listcomp>
    self.child.to_representation(item) for item in iterable
  File "C:\Users\Nick\AppData\Local\Programs\Python\Python310\lib\site-packages\rest_framework\serializers.py", line 507, in to_representation
    for field in fields:
  File "C:\Users\Nick\AppData\Local\Programs\Python\Python310\lib\site-packages\rest_framework\serializers.py", line 368, in _readable_fields
    for field in self.fields.values():
  File "C:\Users\Nick\AppData\Local\Programs\Python\Python310\lib\site-packages\django\utils\functional.py", line 57, in __get__
    res = instance.__dict__[self.name] = self.func(instance)
  File "C:\Users\Nick\AppData\Local\Programs\Python\Python310\lib\site-packages\rest_framework\serializers.py", line 356, in fields
    for key, value in self.get_fields().items():
  File "C:\Users\Nick\AppData\Local\Programs\Python\Python310\lib\site-packages\rest_framework\serializers.py", line 1076, in get_fields
    field_class, field_kwargs = self.build_field(
  File "C:\Users\Nick\AppData\Local\Programs\Python\Python310\lib\site-packages\rest_framework\serializers.py", line 1222, in build_field
    return self.build_unknown_field(field_name, model_class)
  File "C:\Users\Nick\AppData\Local\Programs\Python\Python310\lib\site-packages\rest_framework\serializers.py", line 1340, in build_unknown_field
    raise ImproperlyConfigured(
django.core.exceptions.ImproperlyConfigured: Field name `category` is not valid for model `Advert`.
2024-01-18 16:40:19,181 django.request WARNING  Not Found: /favicon.ico
2024-01-18 16:40:19,822 django.request ERROR    Internal Server Error: /api/content/adverts/
Traceback (most recent call last):
  File "C:\Users\Nick\AppData\Local\Programs\Python\Python310\lib\site-packages\django\core\handlers\exception.py", line 55, in inner
    response = get_response(request)
  File "C:\Users\Nick\AppData\Local\Programs\Python\Python310\lib\site-packages\django\core\handlers\base.py", line 197, in _get_response
    response = wrapped_callback(request, *callback_args, **callback_kwargs)
  File "C:\Users\Nick\AppData\Local\Programs\Python\Python310\lib\site-packages\django\views\decorators\csrf.py", line 56, in wrapper_view
    return view_func(*args, **kwargs)
  File "C:\Users\Nick\AppData\Local\Programs\Python\Python310\lib\site-packages\django\views\generic\base.py", line 104, in view
    return self.dispatch(request, *args, **kwargs)
  File "C:\Users\Nick\AppData\Local\Programs\Python\Python310\lib\site-packages\rest_framework\views.py", line 509, in dispatch
    response = self.handle_exception(exc)
  File "C:\Users\Nick\AppData\Local\Programs\Python\Python310\lib\site-packages\rest_framework\views.py", line 469, in handle_exception
    self.raise_uncaught_exception(exc)
  File "C:\Users\Nick\AppData\Local\Programs\Python\Python310\lib\site-packages\rest_framework\views.py", line 480, in raise_uncaught_exception
    raise exc
  File "C:\Users\Nick\AppData\Local\Programs\Python\Python310\lib\site-packages\rest_framework\views.py", line 506, in dispatch
    response = handler(request, *args, **kwargs)
  File "C:\Users\Nick\Desktop\git\Advert-Project\mytestprj\advert\api\views.py", line 131, in get
    "adverts": serializer.data
  File "C:\Users\Nick\AppData\Local\Programs\Python\Python310\lib\site-packages\rest_framework\serializers.py", line 768, in data
    ret = super().data
  File "C:\Users\Nick\AppData\Local\Programs\Python\Python310\lib\site-packages\rest_framework\serializers.py", line 253, in data
    self._data = self.to_representation(self.instance)
  File "C:\Users\Nick\AppData\Local\Programs\Python\Python310\lib\site-packages\rest_framework\serializers.py", line 686, in to_representation
    return [
  File "C:\Users\Nick\AppData\Local\Programs\Python\Python310\lib\site-packages\rest_framework\serializers.py", line 687, in <listcomp>
    self.child.to_representation(item) for item in iterable
  File "C:\Users\Nick\AppData\Local\Programs\Python\Python310\lib\site-packages\rest_framework\serializers.py", line 507, in to_representation
    for field in fields:
  File "C:\Users\Nick\AppData\Local\Programs\Python\Python310\lib\site-packages\rest_framework\serializers.py", line 368, in _readable_fields
    for field in self.fields.values():
  File "C:\Users\Nick\AppData\Local\Programs\Python\Python310\lib\site-packages\django\utils\functional.py", line 57, in __get__
    res = instance.__dict__[self.name] = self.func(instance)
  File "C:\Users\Nick\AppData\Local\Programs\Python\Python310\lib\site-packages\rest_framework\serializers.py", line 356, in fields
    for key, value in self.get_fields().items():
  File "C:\Users\Nick\AppData\Local\Programs\Python\Python310\lib\site-packages\rest_framework\serializers.py", line 1076, in get_fields
    field_class, field_kwargs = self.build_field(
  File "C:\Users\Nick\AppData\Local\Programs\Python\Python310\lib\site-packages\rest_framework\serializers.py", line 1222, in build_field
    return self.build_unknown_field(field_name, model_class)
  File "C:\Users\Nick\AppData\Local\Programs\Python\Python310\lib\site-packages\rest_framework\serializers.py", line 1340, in build_unknown_field
    raise ImproperlyConfigured(
django.core.exceptions.ImproperlyConfigured: Field name `category` is not valid for model `Advert`.
2024-01-18 16:40:19,995 django.request WARNING  Not Found: /favicon.ico
2024-01-18 16:41:33,264 django.utils.autoreload INFO     C:\Users\Nick\Desktop\git\Advert-Project\mytestprj\advert\api\serializers.py changed, reloading.
2024-01-18 16:41:34,127 django.utils.autoreload INFO     Watching for file changes with StatReloader
2024-01-18 16:41:35,266 django.request WARNING  Not Found: /favicon.ico
2024-01-18 16:42:38,049 django.utils.autoreload INFO     C:\Users\Nick\Desktop\git\Advert-Project\mytestprj\advert\api\serializers.py changed, reloading.
2024-01-18 16:42:38,981 django.utils.autoreload INFO     Watching for file changes with StatReloader
2024-01-18 16:42:40,279 django.request WARNING  Not Found: /favicon.ico
2024-01-21 17:22:06,286 django.utils.autoreload INFO     Watching for file changes with StatReloader
2024-01-21 17:22:07,878 django.request WARNING  Not Found: /
2024-01-21 17:22:07,968 django.request WARNING  Not Found: /favicon.ico
2024-01-21 17:49:32,380 django.utils.autoreload INFO     Watching for file changes with StatReloader
2024-01-21 17:49:33,667 django.request WARNING  Not Found: /
2024-01-21 17:50:09,890 django.request WARNING  Not Found: /api/admin/
2024-01-21 17:54:01,471 django.request WARNING  Not Found: /api/
2024-01-21 17:54:02,628 django.request ERROR    Internal Server Error: /api/schema/
Traceback (most recent call last):
  File "C:\Users\Nick\AppData\Local\Programs\Python\Python310\lib\site-packages\django\core\handlers\exception.py", line 55, in inner
    response = get_response(request)
  File "C:\Users\Nick\AppData\Local\Programs\Python\Python310\lib\site-packages\django\core\handlers\base.py", line 197, in _get_response
    response = wrapped_callback(request, *callback_args, **callback_kwargs)
  File "C:\Users\Nick\AppData\Local\Programs\Python\Python310\lib\site-packages\django\views\decorators\csrf.py", line 56, in wrapper_view
    return view_func(*args, **kwargs)
  File "C:\Users\Nick\AppData\Local\Programs\Python\Python310\lib\site-packages\django\views\generic\base.py", line 104, in view
    return self.dispatch(request, *args, **kwargs)
  File "C:\Users\Nick\AppData\Local\Programs\Python\Python310\lib\site-packages\rest_framework\views.py", line 509, in dispatch
    response = self.handle_exception(exc)
  File "C:\Users\Nick\AppData\Local\Programs\Python\Python310\lib\site-packages\rest_framework\views.py", line 469, in handle_exception
    self.raise_uncaught_exception(exc)
  File "C:\Users\Nick\AppData\Local\Programs\Python\Python310\lib\site-packages\rest_framework\views.py", line 480, in raise_uncaught_exception
    raise exc
  File "C:\Users\Nick\AppData\Local\Programs\Python\Python310\lib\site-packages\rest_framework\views.py", line 506, in dispatch
    response = handler(request, *args, **kwargs)
  File "C:\Users\Nick\AppData\Local\Programs\Python\Python310\lib\site-packages\drf_spectacular\views.py", line 83, in get
    return self._get_schema_response(request)
  File "C:\Users\Nick\AppData\Local\Programs\Python\Python310\lib\site-packages\drf_spectacular\views.py", line 91, in _get_schema_response
    data=generator.get_schema(request=request, public=self.serve_public),
  File "C:\Users\Nick\AppData\Local\Programs\Python\Python310\lib\site-packages\drf_spectacular\generators.py", line 268, in get_schema
    paths=self.parse(request, public),
  File "C:\Users\Nick\AppData\Local\Programs\Python\Python310\lib\site-packages\drf_spectacular\generators.py", line 239, in parse
    operation = view.schema.get_operation(
  File "C:\Users\Nick\AppData\Local\Programs\Python\Python310\lib\site-packages\drf_spectacular\utils.py", line 422, in get_operation
    return super().get_operation(path, path_regex, path_prefix, method, registry)
  File "C:\Users\Nick\AppData\Local\Programs\Python\Python310\lib\site-packages\drf_spectacular\openapi.py", line 98, in get_operation
    operation['responses'] = self._get_response_bodies()
  File "C:\Users\Nick\AppData\Local\Programs\Python\Python310\lib\site-packages\drf_spectacular\openapi.py", line 1355, in _get_response_bodies
    return {'200': self._get_response_for_code(response_serializers, '200', direction=direction)}
  File "C:\Users\Nick\AppData\Local\Programs\Python\Python310\lib\site-packages\drf_spectacular\openapi.py", line 1411, in _get_response_for_code
    component = self.resolve_serializer(serializer, direction)
  File "C:\Users\Nick\AppData\Local\Programs\Python\Python310\lib\site-packages\drf_spectacular\openapi.py", line 1585, in resolve_serializer
    component.schema = self._map_serializer(serializer, direction, bypass_extensions)
  File "C:\Users\Nick\AppData\Local\Programs\Python\Python310\lib\site-packages\drf_spectacular\openapi.py", line 914, in _map_serializer
    schema = self._map_basic_serializer(serializer, direction)
  File "C:\Users\Nick\AppData\Local\Programs\Python\Python310\lib\site-packages\drf_spectacular\openapi.py", line 1006, in _map_basic_serializer
    for field in serializer.fields.values():
  File "C:\Users\Nick\AppData\Local\Programs\Python\Python310\lib\site-packages\django\utils\functional.py", line 57, in __get__
    res = instance.__dict__[self.name] = self.func(instance)
  File "C:\Users\Nick\AppData\Local\Programs\Python\Python310\lib\site-packages\rest_framework\serializers.py", line 356, in fields
    for key, value in self.get_fields().items():
  File "C:\Users\Nick\AppData\Local\Programs\Python\Python310\lib\site-packages\rest_framework\serializers.py", line 1052, in get_fields
    field_names = self.get_field_names(declared_fields, info)
  File "C:\Users\Nick\AppData\Local\Programs\Python\Python310\lib\site-packages\rest_framework\serializers.py", line 1148, in get_field_names
    assert field_name in fields, (
AssertionError: The field 'advert_info' was declared on serializer ProposalSerializer, but has not been included in the 'fields' option.
2024-01-21 17:54:02,713 django.request ERROR    Internal Server Error: /api/schema/
Traceback (most recent call last):
  File "C:\Users\Nick\AppData\Local\Programs\Python\Python310\lib\site-packages\django\core\handlers\exception.py", line 55, in inner
    response = get_response(request)
  File "C:\Users\Nick\AppData\Local\Programs\Python\Python310\lib\site-packages\django\core\handlers\base.py", line 197, in _get_response
    response = wrapped_callback(request, *callback_args, **callback_kwargs)
  File "C:\Users\Nick\AppData\Local\Programs\Python\Python310\lib\site-packages\django\views\decorators\csrf.py", line 56, in wrapper_view
    return view_func(*args, **kwargs)
  File "C:\Users\Nick\AppData\Local\Programs\Python\Python310\lib\site-packages\django\views\generic\base.py", line 104, in view
    return self.dispatch(request, *args, **kwargs)
  File "C:\Users\Nick\AppData\Local\Programs\Python\Python310\lib\site-packages\rest_framework\views.py", line 509, in dispatch
    response = self.handle_exception(exc)
  File "C:\Users\Nick\AppData\Local\Programs\Python\Python310\lib\site-packages\rest_framework\views.py", line 469, in handle_exception
    self.raise_uncaught_exception(exc)
  File "C:\Users\Nick\AppData\Local\Programs\Python\Python310\lib\site-packages\rest_framework\views.py", line 480, in raise_uncaught_exception
    raise exc
  File "C:\Users\Nick\AppData\Local\Programs\Python\Python310\lib\site-packages\rest_framework\views.py", line 506, in dispatch
    response = handler(request, *args, **kwargs)
  File "C:\Users\Nick\AppData\Local\Programs\Python\Python310\lib\site-packages\drf_spectacular\views.py", line 83, in get
    return self._get_schema_response(request)
  File "C:\Users\Nick\AppData\Local\Programs\Python\Python310\lib\site-packages\drf_spectacular\views.py", line 91, in _get_schema_response
    data=generator.get_schema(request=request, public=self.serve_public),
  File "C:\Users\Nick\AppData\Local\Programs\Python\Python310\lib\site-packages\drf_spectacular\generators.py", line 268, in get_schema
    paths=self.parse(request, public),
  File "C:\Users\Nick\AppData\Local\Programs\Python\Python310\lib\site-packages\drf_spectacular\generators.py", line 239, in parse
    operation = view.schema.get_operation(
  File "C:\Users\Nick\AppData\Local\Programs\Python\Python310\lib\site-packages\drf_spectacular\utils.py", line 422, in get_operation
    return super().get_operation(path, path_regex, path_prefix, method, registry)
  File "C:\Users\Nick\AppData\Local\Programs\Python\Python310\lib\site-packages\drf_spectacular\openapi.py", line 98, in get_operation
    operation['responses'] = self._get_response_bodies()
  File "C:\Users\Nick\AppData\Local\Programs\Python\Python310\lib\site-packages\drf_spectacular\openapi.py", line 1355, in _get_response_bodies
    return {'200': self._get_response_for_code(response_serializers, '200', direction=direction)}
  File "C:\Users\Nick\AppData\Local\Programs\Python\Python310\lib\site-packages\drf_spectacular\openapi.py", line 1411, in _get_response_for_code
    component = self.resolve_serializer(serializer, direction)
  File "C:\Users\Nick\AppData\Local\Programs\Python\Python310\lib\site-packages\drf_spectacular\openapi.py", line 1585, in resolve_serializer
    component.schema = self._map_serializer(serializer, direction, bypass_extensions)
  File "C:\Users\Nick\AppData\Local\Programs\Python\Python310\lib\site-packages\drf_spectacular\openapi.py", line 914, in _map_serializer
    schema = self._map_basic_serializer(serializer, direction)
  File "C:\Users\Nick\AppData\Local\Programs\Python\Python310\lib\site-packages\drf_spectacular\openapi.py", line 1006, in _map_basic_serializer
    for field in serializer.fields.values():
  File "C:\Users\Nick\AppData\Local\Programs\Python\Python310\lib\site-packages\django\utils\functional.py", line 57, in __get__
    res = instance.__dict__[self.name] = self.func(instance)
  File "C:\Users\Nick\AppData\Local\Programs\Python\Python310\lib\site-packages\rest_framework\serializers.py", line 356, in fields
    for key, value in self.get_fields().items():
  File "C:\Users\Nick\AppData\Local\Programs\Python\Python310\lib\site-packages\rest_framework\serializers.py", line 1052, in get_fields
    field_names = self.get_field_names(declared_fields, info)
  File "C:\Users\Nick\AppData\Local\Programs\Python\Python310\lib\site-packages\rest_framework\serializers.py", line 1148, in get_field_names
    assert field_name in fields, (
AssertionError: The field 'advert_info' was declared on serializer ProposalSerializer, but has not been included in the 'fields' option.
2024-01-21 17:54:08,808 django.request ERROR    Internal Server Error: /api/schema/
Traceback (most recent call last):
  File "C:\Users\Nick\AppData\Local\Programs\Python\Python310\lib\site-packages\django\core\handlers\exception.py", line 55, in inner
    response = get_response(request)
  File "C:\Users\Nick\AppData\Local\Programs\Python\Python310\lib\site-packages\django\core\handlers\base.py", line 197, in _get_response
    response = wrapped_callback(request, *callback_args, **callback_kwargs)
  File "C:\Users\Nick\AppData\Local\Programs\Python\Python310\lib\site-packages\django\views\decorators\csrf.py", line 56, in wrapper_view
    return view_func(*args, **kwargs)
  File "C:\Users\Nick\AppData\Local\Programs\Python\Python310\lib\site-packages\django\views\generic\base.py", line 104, in view
    return self.dispatch(request, *args, **kwargs)
  File "C:\Users\Nick\AppData\Local\Programs\Python\Python310\lib\site-packages\rest_framework\views.py", line 509, in dispatch
    response = self.handle_exception(exc)
  File "C:\Users\Nick\AppData\Local\Programs\Python\Python310\lib\site-packages\rest_framework\views.py", line 469, in handle_exception
    self.raise_uncaught_exception(exc)
  File "C:\Users\Nick\AppData\Local\Programs\Python\Python310\lib\site-packages\rest_framework\views.py", line 480, in raise_uncaught_exception
    raise exc
  File "C:\Users\Nick\AppData\Local\Programs\Python\Python310\lib\site-packages\rest_framework\views.py", line 506, in dispatch
    response = handler(request, *args, **kwargs)
  File "C:\Users\Nick\AppData\Local\Programs\Python\Python310\lib\site-packages\drf_spectacular\views.py", line 83, in get
    return self._get_schema_response(request)
  File "C:\Users\Nick\AppData\Local\Programs\Python\Python310\lib\site-packages\drf_spectacular\views.py", line 91, in _get_schema_response
    data=generator.get_schema(request=request, public=self.serve_public),
  File "C:\Users\Nick\AppData\Local\Programs\Python\Python310\lib\site-packages\drf_spectacular\generators.py", line 268, in get_schema
    paths=self.parse(request, public),
  File "C:\Users\Nick\AppData\Local\Programs\Python\Python310\lib\site-packages\drf_spectacular\generators.py", line 239, in parse
    operation = view.schema.get_operation(
  File "C:\Users\Nick\AppData\Local\Programs\Python\Python310\lib\site-packages\drf_spectacular\utils.py", line 422, in get_operation
    return super().get_operation(path, path_regex, path_prefix, method, registry)
  File "C:\Users\Nick\AppData\Local\Programs\Python\Python310\lib\site-packages\drf_spectacular\openapi.py", line 98, in get_operation
    operation['responses'] = self._get_response_bodies()
  File "C:\Users\Nick\AppData\Local\Programs\Python\Python310\lib\site-packages\drf_spectacular\openapi.py", line 1355, in _get_response_bodies
    return {'200': self._get_response_for_code(response_serializers, '200', direction=direction)}
  File "C:\Users\Nick\AppData\Local\Programs\Python\Python310\lib\site-packages\drf_spectacular\openapi.py", line 1411, in _get_response_for_code
    component = self.resolve_serializer(serializer, direction)
  File "C:\Users\Nick\AppData\Local\Programs\Python\Python310\lib\site-packages\drf_spectacular\openapi.py", line 1585, in resolve_serializer
    component.schema = self._map_serializer(serializer, direction, bypass_extensions)
  File "C:\Users\Nick\AppData\Local\Programs\Python\Python310\lib\site-packages\drf_spectacular\openapi.py", line 914, in _map_serializer
    schema = self._map_basic_serializer(serializer, direction)
  File "C:\Users\Nick\AppData\Local\Programs\Python\Python310\lib\site-packages\drf_spectacular\openapi.py", line 1006, in _map_basic_serializer
    for field in serializer.fields.values():
  File "C:\Users\Nick\AppData\Local\Programs\Python\Python310\lib\site-packages\django\utils\functional.py", line 57, in __get__
    res = instance.__dict__[self.name] = self.func(instance)
  File "C:\Users\Nick\AppData\Local\Programs\Python\Python310\lib\site-packages\rest_framework\serializers.py", line 356, in fields
    for key, value in self.get_fields().items():
  File "C:\Users\Nick\AppData\Local\Programs\Python\Python310\lib\site-packages\rest_framework\serializers.py", line 1052, in get_fields
    field_names = self.get_field_names(declared_fields, info)
  File "C:\Users\Nick\AppData\Local\Programs\Python\Python310\lib\site-packages\rest_framework\serializers.py", line 1148, in get_field_names
    assert field_name in fields, (
AssertionError: The field 'advert_info' was declared on serializer ProposalSerializer, but has not been included in the 'fields' option.
2024-01-21 17:54:08,911 django.request ERROR    Internal Server Error: /api/schema/
Traceback (most recent call last):
  File "C:\Users\Nick\AppData\Local\Programs\Python\Python310\lib\site-packages\django\core\handlers\exception.py", line 55, in inner
    response = get_response(request)
  File "C:\Users\Nick\AppData\Local\Programs\Python\Python310\lib\site-packages\django\core\handlers\base.py", line 197, in _get_response
    response = wrapped_callback(request, *callback_args, **callback_kwargs)
  File "C:\Users\Nick\AppData\Local\Programs\Python\Python310\lib\site-packages\django\views\decorators\csrf.py", line 56, in wrapper_view
    return view_func(*args, **kwargs)
  File "C:\Users\Nick\AppData\Local\Programs\Python\Python310\lib\site-packages\django\views\generic\base.py", line 104, in view
    return self.dispatch(request, *args, **kwargs)
  File "C:\Users\Nick\AppData\Local\Programs\Python\Python310\lib\site-packages\rest_framework\views.py", line 509, in dispatch
    response = self.handle_exception(exc)
  File "C:\Users\Nick\AppData\Local\Programs\Python\Python310\lib\site-packages\rest_framework\views.py", line 469, in handle_exception
    self.raise_uncaught_exception(exc)
  File "C:\Users\Nick\AppData\Local\Programs\Python\Python310\lib\site-packages\rest_framework\views.py", line 480, in raise_uncaught_exception
    raise exc
  File "C:\Users\Nick\AppData\Local\Programs\Python\Python310\lib\site-packages\rest_framework\views.py", line 506, in dispatch
    response = handler(request, *args, **kwargs)
  File "C:\Users\Nick\AppData\Local\Programs\Python\Python310\lib\site-packages\drf_spectacular\views.py", line 83, in get
    return self._get_schema_response(request)
  File "C:\Users\Nick\AppData\Local\Programs\Python\Python310\lib\site-packages\drf_spectacular\views.py", line 91, in _get_schema_response
    data=generator.get_schema(request=request, public=self.serve_public),
  File "C:\Users\Nick\AppData\Local\Programs\Python\Python310\lib\site-packages\drf_spectacular\generators.py", line 268, in get_schema
    paths=self.parse(request, public),
  File "C:\Users\Nick\AppData\Local\Programs\Python\Python310\lib\site-packages\drf_spectacular\generators.py", line 239, in parse
    operation = view.schema.get_operation(
  File "C:\Users\Nick\AppData\Local\Programs\Python\Python310\lib\site-packages\drf_spectacular\utils.py", line 422, in get_operation
    return super().get_operation(path, path_regex, path_prefix, method, registry)
  File "C:\Users\Nick\AppData\Local\Programs\Python\Python310\lib\site-packages\drf_spectacular\openapi.py", line 98, in get_operation
    operation['responses'] = self._get_response_bodies()
  File "C:\Users\Nick\AppData\Local\Programs\Python\Python310\lib\site-packages\drf_spectacular\openapi.py", line 1355, in _get_response_bodies
    return {'200': self._get_response_for_code(response_serializers, '200', direction=direction)}
  File "C:\Users\Nick\AppData\Local\Programs\Python\Python310\lib\site-packages\drf_spectacular\openapi.py", line 1411, in _get_response_for_code
    component = self.resolve_serializer(serializer, direction)
  File "C:\Users\Nick\AppData\Local\Programs\Python\Python310\lib\site-packages\drf_spectacular\openapi.py", line 1585, in resolve_serializer
    component.schema = self._map_serializer(serializer, direction, bypass_extensions)
  File "C:\Users\Nick\AppData\Local\Programs\Python\Python310\lib\site-packages\drf_spectacular\openapi.py", line 914, in _map_serializer
    schema = self._map_basic_serializer(serializer, direction)
  File "C:\Users\Nick\AppData\Local\Programs\Python\Python310\lib\site-packages\drf_spectacular\openapi.py", line 1006, in _map_basic_serializer
    for field in serializer.fields.values():
  File "C:\Users\Nick\AppData\Local\Programs\Python\Python310\lib\site-packages\django\utils\functional.py", line 57, in __get__
    res = instance.__dict__[self.name] = self.func(instance)
  File "C:\Users\Nick\AppData\Local\Programs\Python\Python310\lib\site-packages\rest_framework\serializers.py", line 356, in fields
    for key, value in self.get_fields().items():
  File "C:\Users\Nick\AppData\Local\Programs\Python\Python310\lib\site-packages\rest_framework\serializers.py", line 1052, in get_fields
    field_names = self.get_field_names(declared_fields, info)
  File "C:\Users\Nick\AppData\Local\Programs\Python\Python310\lib\site-packages\rest_framework\serializers.py", line 1148, in get_field_names
    assert field_name in fields, (
AssertionError: The field 'advert_info' was declared on serializer ProposalSerializer, but has not been included in the 'fields' option.
2024-01-21 17:54:10,141 django.request ERROR    Internal Server Error: /api/schema/
Traceback (most recent call last):
  File "C:\Users\Nick\AppData\Local\Programs\Python\Python310\lib\site-packages\django\core\handlers\exception.py", line 55, in inner
    response = get_response(request)
  File "C:\Users\Nick\AppData\Local\Programs\Python\Python310\lib\site-packages\django\core\handlers\base.py", line 197, in _get_response
    response = wrapped_callback(request, *callback_args, **callback_kwargs)
  File "C:\Users\Nick\AppData\Local\Programs\Python\Python310\lib\site-packages\django\views\decorators\csrf.py", line 56, in wrapper_view
    return view_func(*args, **kwargs)
  File "C:\Users\Nick\AppData\Local\Programs\Python\Python310\lib\site-packages\django\views\generic\base.py", line 104, in view
    return self.dispatch(request, *args, **kwargs)
  File "C:\Users\Nick\AppData\Local\Programs\Python\Python310\lib\site-packages\rest_framework\views.py", line 509, in dispatch
    response = self.handle_exception(exc)
  File "C:\Users\Nick\AppData\Local\Programs\Python\Python310\lib\site-packages\rest_framework\views.py", line 469, in handle_exception
    self.raise_uncaught_exception(exc)
  File "C:\Users\Nick\AppData\Local\Programs\Python\Python310\lib\site-packages\rest_framework\views.py", line 480, in raise_uncaught_exception
    raise exc
  File "C:\Users\Nick\AppData\Local\Programs\Python\Python310\lib\site-packages\rest_framework\views.py", line 506, in dispatch
    response = handler(request, *args, **kwargs)
  File "C:\Users\Nick\AppData\Local\Programs\Python\Python310\lib\site-packages\drf_spectacular\views.py", line 83, in get
    return self._get_schema_response(request)
  File "C:\Users\Nick\AppData\Local\Programs\Python\Python310\lib\site-packages\drf_spectacular\views.py", line 91, in _get_schema_response
    data=generator.get_schema(request=request, public=self.serve_public),
  File "C:\Users\Nick\AppData\Local\Programs\Python\Python310\lib\site-packages\drf_spectacular\generators.py", line 268, in get_schema
    paths=self.parse(request, public),
  File "C:\Users\Nick\AppData\Local\Programs\Python\Python310\lib\site-packages\drf_spectacular\generators.py", line 239, in parse
    operation = view.schema.get_operation(
  File "C:\Users\Nick\AppData\Local\Programs\Python\Python310\lib\site-packages\drf_spectacular\utils.py", line 422, in get_operation
    return super().get_operation(path, path_regex, path_prefix, method, registry)
  File "C:\Users\Nick\AppData\Local\Programs\Python\Python310\lib\site-packages\drf_spectacular\openapi.py", line 98, in get_operation
    operation['responses'] = self._get_response_bodies()
  File "C:\Users\Nick\AppData\Local\Programs\Python\Python310\lib\site-packages\drf_spectacular\openapi.py", line 1355, in _get_response_bodies
    return {'200': self._get_response_for_code(response_serializers, '200', direction=direction)}
  File "C:\Users\Nick\AppData\Local\Programs\Python\Python310\lib\site-packages\drf_spectacular\openapi.py", line 1411, in _get_response_for_code
    component = self.resolve_serializer(serializer, direction)
  File "C:\Users\Nick\AppData\Local\Programs\Python\Python310\lib\site-packages\drf_spectacular\openapi.py", line 1585, in resolve_serializer
    component.schema = self._map_serializer(serializer, direction, bypass_extensions)
  File "C:\Users\Nick\AppData\Local\Programs\Python\Python310\lib\site-packages\drf_spectacular\openapi.py", line 914, in _map_serializer
    schema = self._map_basic_serializer(serializer, direction)
  File "C:\Users\Nick\AppData\Local\Programs\Python\Python310\lib\site-packages\drf_spectacular\openapi.py", line 1006, in _map_basic_serializer
    for field in serializer.fields.values():
  File "C:\Users\Nick\AppData\Local\Programs\Python\Python310\lib\site-packages\django\utils\functional.py", line 57, in __get__
    res = instance.__dict__[self.name] = self.func(instance)
  File "C:\Users\Nick\AppData\Local\Programs\Python\Python310\lib\site-packages\rest_framework\serializers.py", line 356, in fields
    for key, value in self.get_fields().items():
  File "C:\Users\Nick\AppData\Local\Programs\Python\Python310\lib\site-packages\rest_framework\serializers.py", line 1052, in get_fields
    field_names = self.get_field_names(declared_fields, info)
  File "C:\Users\Nick\AppData\Local\Programs\Python\Python310\lib\site-packages\rest_framework\serializers.py", line 1148, in get_field_names
    assert field_name in fields, (
AssertionError: The field 'advert_info' was declared on serializer ProposalSerializer, but has not been included in the 'fields' option.
2024-01-21 17:54:12,556 django.request ERROR    Internal Server Error: /api/schema/
Traceback (most recent call last):
  File "C:\Users\Nick\AppData\Local\Programs\Python\Python310\lib\site-packages\django\core\handlers\exception.py", line 55, in inner
    response = get_response(request)
  File "C:\Users\Nick\AppData\Local\Programs\Python\Python310\lib\site-packages\django\core\handlers\base.py", line 197, in _get_response
    response = wrapped_callback(request, *callback_args, **callback_kwargs)
  File "C:\Users\Nick\AppData\Local\Programs\Python\Python310\lib\site-packages\django\views\decorators\csrf.py", line 56, in wrapper_view
    return view_func(*args, **kwargs)
  File "C:\Users\Nick\AppData\Local\Programs\Python\Python310\lib\site-packages\django\views\generic\base.py", line 104, in view
    return self.dispatch(request, *args, **kwargs)
  File "C:\Users\Nick\AppData\Local\Programs\Python\Python310\lib\site-packages\rest_framework\views.py", line 509, in dispatch
    response = self.handle_exception(exc)
  File "C:\Users\Nick\AppData\Local\Programs\Python\Python310\lib\site-packages\rest_framework\views.py", line 469, in handle_exception
    self.raise_uncaught_exception(exc)
  File "C:\Users\Nick\AppData\Local\Programs\Python\Python310\lib\site-packages\rest_framework\views.py", line 480, in raise_uncaught_exception
    raise exc
  File "C:\Users\Nick\AppData\Local\Programs\Python\Python310\lib\site-packages\rest_framework\views.py", line 506, in dispatch
    response = handler(request, *args, **kwargs)
  File "C:\Users\Nick\AppData\Local\Programs\Python\Python310\lib\site-packages\drf_spectacular\views.py", line 83, in get
    return self._get_schema_response(request)
  File "C:\Users\Nick\AppData\Local\Programs\Python\Python310\lib\site-packages\drf_spectacular\views.py", line 91, in _get_schema_response
    data=generator.get_schema(request=request, public=self.serve_public),
  File "C:\Users\Nick\AppData\Local\Programs\Python\Python310\lib\site-packages\drf_spectacular\generators.py", line 268, in get_schema
    paths=self.parse(request, public),
  File "C:\Users\Nick\AppData\Local\Programs\Python\Python310\lib\site-packages\drf_spectacular\generators.py", line 239, in parse
    operation = view.schema.get_operation(
  File "C:\Users\Nick\AppData\Local\Programs\Python\Python310\lib\site-packages\drf_spectacular\utils.py", line 422, in get_operation
    return super().get_operation(path, path_regex, path_prefix, method, registry)
  File "C:\Users\Nick\AppData\Local\Programs\Python\Python310\lib\site-packages\drf_spectacular\openapi.py", line 98, in get_operation
    operation['responses'] = self._get_response_bodies()
  File "C:\Users\Nick\AppData\Local\Programs\Python\Python310\lib\site-packages\drf_spectacular\openapi.py", line 1355, in _get_response_bodies
    return {'200': self._get_response_for_code(response_serializers, '200', direction=direction)}
  File "C:\Users\Nick\AppData\Local\Programs\Python\Python310\lib\site-packages\drf_spectacular\openapi.py", line 1411, in _get_response_for_code
    component = self.resolve_serializer(serializer, direction)
  File "C:\Users\Nick\AppData\Local\Programs\Python\Python310\lib\site-packages\drf_spectacular\openapi.py", line 1585, in resolve_serializer
    component.schema = self._map_serializer(serializer, direction, bypass_extensions)
  File "C:\Users\Nick\AppData\Local\Programs\Python\Python310\lib\site-packages\drf_spectacular\openapi.py", line 914, in _map_serializer
    schema = self._map_basic_serializer(serializer, direction)
  File "C:\Users\Nick\AppData\Local\Programs\Python\Python310\lib\site-packages\drf_spectacular\openapi.py", line 1006, in _map_basic_serializer
    for field in serializer.fields.values():
  File "C:\Users\Nick\AppData\Local\Programs\Python\Python310\lib\site-packages\django\utils\functional.py", line 57, in __get__
    res = instance.__dict__[self.name] = self.func(instance)
  File "C:\Users\Nick\AppData\Local\Programs\Python\Python310\lib\site-packages\rest_framework\serializers.py", line 356, in fields
    for key, value in self.get_fields().items():
  File "C:\Users\Nick\AppData\Local\Programs\Python\Python310\lib\site-packages\rest_framework\serializers.py", line 1052, in get_fields
    field_names = self.get_field_names(declared_fields, info)
  File "C:\Users\Nick\AppData\Local\Programs\Python\Python310\lib\site-packages\rest_framework\serializers.py", line 1148, in get_field_names
    assert field_name in fields, (
AssertionError: The field 'advert_info' was declared on serializer ProposalSerializer, but has not been included in the 'fields' option.
2024-01-21 17:54:16,086 django.request ERROR    Internal Server Error: /api/schema/
Traceback (most recent call last):
  File "C:\Users\Nick\AppData\Local\Programs\Python\Python310\lib\site-packages\django\core\handlers\exception.py", line 55, in inner
    response = get_response(request)
  File "C:\Users\Nick\AppData\Local\Programs\Python\Python310\lib\site-packages\django\core\handlers\base.py", line 197, in _get_response
    response = wrapped_callback(request, *callback_args, **callback_kwargs)
  File "C:\Users\Nick\AppData\Local\Programs\Python\Python310\lib\site-packages\django\views\decorators\csrf.py", line 56, in wrapper_view
    return view_func(*args, **kwargs)
  File "C:\Users\Nick\AppData\Local\Programs\Python\Python310\lib\site-packages\django\views\generic\base.py", line 104, in view
    return self.dispatch(request, *args, **kwargs)
  File "C:\Users\Nick\AppData\Local\Programs\Python\Python310\lib\site-packages\rest_framework\views.py", line 509, in dispatch
    response = self.handle_exception(exc)
  File "C:\Users\Nick\AppData\Local\Programs\Python\Python310\lib\site-packages\rest_framework\views.py", line 469, in handle_exception
    self.raise_uncaught_exception(exc)
  File "C:\Users\Nick\AppData\Local\Programs\Python\Python310\lib\site-packages\rest_framework\views.py", line 480, in raise_uncaught_exception
    raise exc
  File "C:\Users\Nick\AppData\Local\Programs\Python\Python310\lib\site-packages\rest_framework\views.py", line 506, in dispatch
    response = handler(request, *args, **kwargs)
  File "C:\Users\Nick\AppData\Local\Programs\Python\Python310\lib\site-packages\drf_spectacular\views.py", line 83, in get
    return self._get_schema_response(request)
  File "C:\Users\Nick\AppData\Local\Programs\Python\Python310\lib\site-packages\drf_spectacular\views.py", line 91, in _get_schema_response
    data=generator.get_schema(request=request, public=self.serve_public),
  File "C:\Users\Nick\AppData\Local\Programs\Python\Python310\lib\site-packages\drf_spectacular\generators.py", line 268, in get_schema
    paths=self.parse(request, public),
  File "C:\Users\Nick\AppData\Local\Programs\Python\Python310\lib\site-packages\drf_spectacular\generators.py", line 239, in parse
    operation = view.schema.get_operation(
  File "C:\Users\Nick\AppData\Local\Programs\Python\Python310\lib\site-packages\drf_spectacular\utils.py", line 422, in get_operation
    return super().get_operation(path, path_regex, path_prefix, method, registry)
  File "C:\Users\Nick\AppData\Local\Programs\Python\Python310\lib\site-packages\drf_spectacular\openapi.py", line 98, in get_operation
    operation['responses'] = self._get_response_bodies()
  File "C:\Users\Nick\AppData\Local\Programs\Python\Python310\lib\site-packages\drf_spectacular\openapi.py", line 1355, in _get_response_bodies
    return {'200': self._get_response_for_code(response_serializers, '200', direction=direction)}
  File "C:\Users\Nick\AppData\Local\Programs\Python\Python310\lib\site-packages\drf_spectacular\openapi.py", line 1411, in _get_response_for_code
    component = self.resolve_serializer(serializer, direction)
  File "C:\Users\Nick\AppData\Local\Programs\Python\Python310\lib\site-packages\drf_spectacular\openapi.py", line 1585, in resolve_serializer
    component.schema = self._map_serializer(serializer, direction, bypass_extensions)
  File "C:\Users\Nick\AppData\Local\Programs\Python\Python310\lib\site-packages\drf_spectacular\openapi.py", line 914, in _map_serializer
    schema = self._map_basic_serializer(serializer, direction)
  File "C:\Users\Nick\AppData\Local\Programs\Python\Python310\lib\site-packages\drf_spectacular\openapi.py", line 1006, in _map_basic_serializer
    for field in serializer.fields.values():
  File "C:\Users\Nick\AppData\Local\Programs\Python\Python310\lib\site-packages\django\utils\functional.py", line 57, in __get__
    res = instance.__dict__[self.name] = self.func(instance)
  File "C:\Users\Nick\AppData\Local\Programs\Python\Python310\lib\site-packages\rest_framework\serializers.py", line 356, in fields
    for key, value in self.get_fields().items():
  File "C:\Users\Nick\AppData\Local\Programs\Python\Python310\lib\site-packages\rest_framework\serializers.py", line 1052, in get_fields
    field_names = self.get_field_names(declared_fields, info)
  File "C:\Users\Nick\AppData\Local\Programs\Python\Python310\lib\site-packages\rest_framework\serializers.py", line 1148, in get_field_names
    assert field_name in fields, (
AssertionError: The field 'advert_info' was declared on serializer ProposalSerializer, but has not been included in the 'fields' option.
2024-01-21 17:54:16,201 django.request ERROR    Internal Server Error: /api/schema/
Traceback (most recent call last):
  File "C:\Users\Nick\AppData\Local\Programs\Python\Python310\lib\site-packages\django\core\handlers\exception.py", line 55, in inner
    response = get_response(request)
  File "C:\Users\Nick\AppData\Local\Programs\Python\Python310\lib\site-packages\django\core\handlers\base.py", line 197, in _get_response
    response = wrapped_callback(request, *callback_args, **callback_kwargs)
  File "C:\Users\Nick\AppData\Local\Programs\Python\Python310\lib\site-packages\django\views\decorators\csrf.py", line 56, in wrapper_view
    return view_func(*args, **kwargs)
  File "C:\Users\Nick\AppData\Local\Programs\Python\Python310\lib\site-packages\django\views\generic\base.py", line 104, in view
    return self.dispatch(request, *args, **kwargs)
  File "C:\Users\Nick\AppData\Local\Programs\Python\Python310\lib\site-packages\rest_framework\views.py", line 509, in dispatch
    response = self.handle_exception(exc)
  File "C:\Users\Nick\AppData\Local\Programs\Python\Python310\lib\site-packages\rest_framework\views.py", line 469, in handle_exception
    self.raise_uncaught_exception(exc)
  File "C:\Users\Nick\AppData\Local\Programs\Python\Python310\lib\site-packages\rest_framework\views.py", line 480, in raise_uncaught_exception
    raise exc
  File "C:\Users\Nick\AppData\Local\Programs\Python\Python310\lib\site-packages\rest_framework\views.py", line 506, in dispatch
    response = handler(request, *args, **kwargs)
  File "C:\Users\Nick\AppData\Local\Programs\Python\Python310\lib\site-packages\drf_spectacular\views.py", line 83, in get
    return self._get_schema_response(request)
  File "C:\Users\Nick\AppData\Local\Programs\Python\Python310\lib\site-packages\drf_spectacular\views.py", line 91, in _get_schema_response
    data=generator.get_schema(request=request, public=self.serve_public),
  File "C:\Users\Nick\AppData\Local\Programs\Python\Python310\lib\site-packages\drf_spectacular\generators.py", line 268, in get_schema
    paths=self.parse(request, public),
  File "C:\Users\Nick\AppData\Local\Programs\Python\Python310\lib\site-packages\drf_spectacular\generators.py", line 239, in parse
    operation = view.schema.get_operation(
  File "C:\Users\Nick\AppData\Local\Programs\Python\Python310\lib\site-packages\drf_spectacular\utils.py", line 422, in get_operation
    return super().get_operation(path, path_regex, path_prefix, method, registry)
  File "C:\Users\Nick\AppData\Local\Programs\Python\Python310\lib\site-packages\drf_spectacular\openapi.py", line 98, in get_operation
    operation['responses'] = self._get_response_bodies()
  File "C:\Users\Nick\AppData\Local\Programs\Python\Python310\lib\site-packages\drf_spectacular\openapi.py", line 1355, in _get_response_bodies
    return {'200': self._get_response_for_code(response_serializers, '200', direction=direction)}
  File "C:\Users\Nick\AppData\Local\Programs\Python\Python310\lib\site-packages\drf_spectacular\openapi.py", line 1411, in _get_response_for_code
    component = self.resolve_serializer(serializer, direction)
  File "C:\Users\Nick\AppData\Local\Programs\Python\Python310\lib\site-packages\drf_spectacular\openapi.py", line 1585, in resolve_serializer
    component.schema = self._map_serializer(serializer, direction, bypass_extensions)
  File "C:\Users\Nick\AppData\Local\Programs\Python\Python310\lib\site-packages\drf_spectacular\openapi.py", line 914, in _map_serializer
    schema = self._map_basic_serializer(serializer, direction)
  File "C:\Users\Nick\AppData\Local\Programs\Python\Python310\lib\site-packages\drf_spectacular\openapi.py", line 1006, in _map_basic_serializer
    for field in serializer.fields.values():
  File "C:\Users\Nick\AppData\Local\Programs\Python\Python310\lib\site-packages\django\utils\functional.py", line 57, in __get__
    res = instance.__dict__[self.name] = self.func(instance)
  File "C:\Users\Nick\AppData\Local\Programs\Python\Python310\lib\site-packages\rest_framework\serializers.py", line 356, in fields
    for key, value in self.get_fields().items():
  File "C:\Users\Nick\AppData\Local\Programs\Python\Python310\lib\site-packages\rest_framework\serializers.py", line 1052, in get_fields
    field_names = self.get_field_names(declared_fields, info)
  File "C:\Users\Nick\AppData\Local\Programs\Python\Python310\lib\site-packages\rest_framework\serializers.py", line 1148, in get_field_names
    assert field_name in fields, (
AssertionError: The field 'advert_info' was declared on serializer ProposalSerializer, but has not been included in the 'fields' option.
2024-01-21 17:54:21,647 django.request ERROR    Internal Server Error: /api/schema/
Traceback (most recent call last):
  File "C:\Users\Nick\AppData\Local\Programs\Python\Python310\lib\site-packages\django\core\handlers\exception.py", line 55, in inner
    response = get_response(request)
  File "C:\Users\Nick\AppData\Local\Programs\Python\Python310\lib\site-packages\django\core\handlers\base.py", line 197, in _get_response
    response = wrapped_callback(request, *callback_args, **callback_kwargs)
  File "C:\Users\Nick\AppData\Local\Programs\Python\Python310\lib\site-packages\django\views\decorators\csrf.py", line 56, in wrapper_view
    return view_func(*args, **kwargs)
  File "C:\Users\Nick\AppData\Local\Programs\Python\Python310\lib\site-packages\django\views\generic\base.py", line 104, in view
    return self.dispatch(request, *args, **kwargs)
  File "C:\Users\Nick\AppData\Local\Programs\Python\Python310\lib\site-packages\rest_framework\views.py", line 509, in dispatch
    response = self.handle_exception(exc)
  File "C:\Users\Nick\AppData\Local\Programs\Python\Python310\lib\site-packages\rest_framework\views.py", line 469, in handle_exception
    self.raise_uncaught_exception(exc)
  File "C:\Users\Nick\AppData\Local\Programs\Python\Python310\lib\site-packages\rest_framework\views.py", line 480, in raise_uncaught_exception
    raise exc
  File "C:\Users\Nick\AppData\Local\Programs\Python\Python310\lib\site-packages\rest_framework\views.py", line 506, in dispatch
    response = handler(request, *args, **kwargs)
  File "C:\Users\Nick\AppData\Local\Programs\Python\Python310\lib\site-packages\drf_spectacular\views.py", line 83, in get
    return self._get_schema_response(request)
  File "C:\Users\Nick\AppData\Local\Programs\Python\Python310\lib\site-packages\drf_spectacular\views.py", line 91, in _get_schema_response
    data=generator.get_schema(request=request, public=self.serve_public),
  File "C:\Users\Nick\AppData\Local\Programs\Python\Python310\lib\site-packages\drf_spectacular\generators.py", line 268, in get_schema
    paths=self.parse(request, public),
  File "C:\Users\Nick\AppData\Local\Programs\Python\Python310\lib\site-packages\drf_spectacular\generators.py", line 239, in parse
    operation = view.schema.get_operation(
  File "C:\Users\Nick\AppData\Local\Programs\Python\Python310\lib\site-packages\drf_spectacular\utils.py", line 422, in get_operation
    return super().get_operation(path, path_regex, path_prefix, method, registry)
  File "C:\Users\Nick\AppData\Local\Programs\Python\Python310\lib\site-packages\drf_spectacular\openapi.py", line 98, in get_operation
    operation['responses'] = self._get_response_bodies()
  File "C:\Users\Nick\AppData\Local\Programs\Python\Python310\lib\site-packages\drf_spectacular\openapi.py", line 1355, in _get_response_bodies
    return {'200': self._get_response_for_code(response_serializers, '200', direction=direction)}
  File "C:\Users\Nick\AppData\Local\Programs\Python\Python310\lib\site-packages\drf_spectacular\openapi.py", line 1411, in _get_response_for_code
    component = self.resolve_serializer(serializer, direction)
  File "C:\Users\Nick\AppData\Local\Programs\Python\Python310\lib\site-packages\drf_spectacular\openapi.py", line 1585, in resolve_serializer
    component.schema = self._map_serializer(serializer, direction, bypass_extensions)
  File "C:\Users\Nick\AppData\Local\Programs\Python\Python310\lib\site-packages\drf_spectacular\openapi.py", line 914, in _map_serializer
    schema = self._map_basic_serializer(serializer, direction)
  File "C:\Users\Nick\AppData\Local\Programs\Python\Python310\lib\site-packages\drf_spectacular\openapi.py", line 1006, in _map_basic_serializer
    for field in serializer.fields.values():
  File "C:\Users\Nick\AppData\Local\Programs\Python\Python310\lib\site-packages\django\utils\functional.py", line 57, in __get__
    res = instance.__dict__[self.name] = self.func(instance)
  File "C:\Users\Nick\AppData\Local\Programs\Python\Python310\lib\site-packages\rest_framework\serializers.py", line 356, in fields
    for key, value in self.get_fields().items():
  File "C:\Users\Nick\AppData\Local\Programs\Python\Python310\lib\site-packages\rest_framework\serializers.py", line 1052, in get_fields
    field_names = self.get_field_names(declared_fields, info)
  File "C:\Users\Nick\AppData\Local\Programs\Python\Python310\lib\site-packages\rest_framework\serializers.py", line 1148, in get_field_names
    assert field_name in fields, (
AssertionError: The field 'advert_info' was declared on serializer ProposalSerializer, but has not been included in the 'fields' option.
2024-01-21 17:54:21,730 django.request ERROR    Internal Server Error: /api/schema/
Traceback (most recent call last):
  File "C:\Users\Nick\AppData\Local\Programs\Python\Python310\lib\site-packages\django\core\handlers\exception.py", line 55, in inner
    response = get_response(request)
  File "C:\Users\Nick\AppData\Local\Programs\Python\Python310\lib\site-packages\django\core\handlers\base.py", line 197, in _get_response
    response = wrapped_callback(request, *callback_args, **callback_kwargs)
  File "C:\Users\Nick\AppData\Local\Programs\Python\Python310\lib\site-packages\django\views\decorators\csrf.py", line 56, in wrapper_view
    return view_func(*args, **kwargs)
  File "C:\Users\Nick\AppData\Local\Programs\Python\Python310\lib\site-packages\django\views\generic\base.py", line 104, in view
    return self.dispatch(request, *args, **kwargs)
  File "C:\Users\Nick\AppData\Local\Programs\Python\Python310\lib\site-packages\rest_framework\views.py", line 509, in dispatch
    response = self.handle_exception(exc)
  File "C:\Users\Nick\AppData\Local\Programs\Python\Python310\lib\site-packages\rest_framework\views.py", line 469, in handle_exception
    self.raise_uncaught_exception(exc)
  File "C:\Users\Nick\AppData\Local\Programs\Python\Python310\lib\site-packages\rest_framework\views.py", line 480, in raise_uncaught_exception
    raise exc
  File "C:\Users\Nick\AppData\Local\Programs\Python\Python310\lib\site-packages\rest_framework\views.py", line 506, in dispatch
    response = handler(request, *args, **kwargs)
  File "C:\Users\Nick\AppData\Local\Programs\Python\Python310\lib\site-packages\drf_spectacular\views.py", line 83, in get
    return self._get_schema_response(request)
  File "C:\Users\Nick\AppData\Local\Programs\Python\Python310\lib\site-packages\drf_spectacular\views.py", line 91, in _get_schema_response
    data=generator.get_schema(request=request, public=self.serve_public),
  File "C:\Users\Nick\AppData\Local\Programs\Python\Python310\lib\site-packages\drf_spectacular\generators.py", line 268, in get_schema
    paths=self.parse(request, public),
  File "C:\Users\Nick\AppData\Local\Programs\Python\Python310\lib\site-packages\drf_spectacular\generators.py", line 239, in parse
    operation = view.schema.get_operation(
  File "C:\Users\Nick\AppData\Local\Programs\Python\Python310\lib\site-packages\drf_spectacular\utils.py", line 422, in get_operation
    return super().get_operation(path, path_regex, path_prefix, method, registry)
  File "C:\Users\Nick\AppData\Local\Programs\Python\Python310\lib\site-packages\drf_spectacular\openapi.py", line 98, in get_operation
    operation['responses'] = self._get_response_bodies()
  File "C:\Users\Nick\AppData\Local\Programs\Python\Python310\lib\site-packages\drf_spectacular\openapi.py", line 1355, in _get_response_bodies
    return {'200': self._get_response_for_code(response_serializers, '200', direction=direction)}
  File "C:\Users\Nick\AppData\Local\Programs\Python\Python310\lib\site-packages\drf_spectacular\openapi.py", line 1411, in _get_response_for_code
    component = self.resolve_serializer(serializer, direction)
  File "C:\Users\Nick\AppData\Local\Programs\Python\Python310\lib\site-packages\drf_spectacular\openapi.py", line 1585, in resolve_serializer
    component.schema = self._map_serializer(serializer, direction, bypass_extensions)
  File "C:\Users\Nick\AppData\Local\Programs\Python\Python310\lib\site-packages\drf_spectacular\openapi.py", line 914, in _map_serializer
    schema = self._map_basic_serializer(serializer, direction)
  File "C:\Users\Nick\AppData\Local\Programs\Python\Python310\lib\site-packages\drf_spectacular\openapi.py", line 1006, in _map_basic_serializer
    for field in serializer.fields.values():
  File "C:\Users\Nick\AppData\Local\Programs\Python\Python310\lib\site-packages\django\utils\functional.py", line 57, in __get__
    res = instance.__dict__[self.name] = self.func(instance)
  File "C:\Users\Nick\AppData\Local\Programs\Python\Python310\lib\site-packages\rest_framework\serializers.py", line 356, in fields
    for key, value in self.get_fields().items():
  File "C:\Users\Nick\AppData\Local\Programs\Python\Python310\lib\site-packages\rest_framework\serializers.py", line 1052, in get_fields
    field_names = self.get_field_names(declared_fields, info)
  File "C:\Users\Nick\AppData\Local\Programs\Python\Python310\lib\site-packages\rest_framework\serializers.py", line 1148, in get_field_names
    assert field_name in fields, (
AssertionError: The field 'advert_info' was declared on serializer ProposalSerializer, but has not been included in the 'fields' option.
2024-01-21 17:54:33,437 django.request WARNING  Not Found: /api/
2024-01-21 17:55:28,117 django.utils.autoreload INFO     C:\Users\Nick\Desktop\git\Advert-Project\mytestprj\advert\api\views.py changed, reloading.
2024-01-21 17:55:28,632 django.utils.autoreload INFO     Watching for file changes with StatReloader
2024-01-21 17:55:30,140 django.request WARNING  Not Found: /
2024-01-21 17:55:43,370 django.request ERROR    Internal Server Error: /api/schema/
Traceback (most recent call last):
  File "C:\Users\Nick\AppData\Local\Programs\Python\Python310\lib\site-packages\django\core\handlers\exception.py", line 55, in inner
    response = get_response(request)
  File "C:\Users\Nick\AppData\Local\Programs\Python\Python310\lib\site-packages\django\core\handlers\base.py", line 197, in _get_response
    response = wrapped_callback(request, *callback_args, **callback_kwargs)
  File "C:\Users\Nick\AppData\Local\Programs\Python\Python310\lib\site-packages\django\views\decorators\csrf.py", line 56, in wrapper_view
    return view_func(*args, **kwargs)
  File "C:\Users\Nick\AppData\Local\Programs\Python\Python310\lib\site-packages\django\views\generic\base.py", line 104, in view
    return self.dispatch(request, *args, **kwargs)
  File "C:\Users\Nick\AppData\Local\Programs\Python\Python310\lib\site-packages\rest_framework\views.py", line 509, in dispatch
    response = self.handle_exception(exc)
  File "C:\Users\Nick\AppData\Local\Programs\Python\Python310\lib\site-packages\rest_framework\views.py", line 469, in handle_exception
    self.raise_uncaught_exception(exc)
  File "C:\Users\Nick\AppData\Local\Programs\Python\Python310\lib\site-packages\rest_framework\views.py", line 480, in raise_uncaught_exception
    raise exc
  File "C:\Users\Nick\AppData\Local\Programs\Python\Python310\lib\site-packages\rest_framework\views.py", line 506, in dispatch
    response = handler(request, *args, **kwargs)
  File "C:\Users\Nick\AppData\Local\Programs\Python\Python310\lib\site-packages\drf_spectacular\views.py", line 83, in get
    return self._get_schema_response(request)
  File "C:\Users\Nick\AppData\Local\Programs\Python\Python310\lib\site-packages\drf_spectacular\views.py", line 91, in _get_schema_response
    data=generator.get_schema(request=request, public=self.serve_public),
  File "C:\Users\Nick\AppData\Local\Programs\Python\Python310\lib\site-packages\drf_spectacular\generators.py", line 268, in get_schema
    paths=self.parse(request, public),
  File "C:\Users\Nick\AppData\Local\Programs\Python\Python310\lib\site-packages\drf_spectacular\generators.py", line 239, in parse
    operation = view.schema.get_operation(
  File "C:\Users\Nick\AppData\Local\Programs\Python\Python310\lib\site-packages\drf_spectacular\utils.py", line 422, in get_operation
    return super().get_operation(path, path_regex, path_prefix, method, registry)
  File "C:\Users\Nick\AppData\Local\Programs\Python\Python310\lib\site-packages\drf_spectacular\openapi.py", line 98, in get_operation
    operation['responses'] = self._get_response_bodies()
  File "C:\Users\Nick\AppData\Local\Programs\Python\Python310\lib\site-packages\drf_spectacular\openapi.py", line 1355, in _get_response_bodies
    return {'200': self._get_response_for_code(response_serializers, '200', direction=direction)}
  File "C:\Users\Nick\AppData\Local\Programs\Python\Python310\lib\site-packages\drf_spectacular\openapi.py", line 1411, in _get_response_for_code
    component = self.resolve_serializer(serializer, direction)
  File "C:\Users\Nick\AppData\Local\Programs\Python\Python310\lib\site-packages\drf_spectacular\openapi.py", line 1585, in resolve_serializer
    component.schema = self._map_serializer(serializer, direction, bypass_extensions)
  File "C:\Users\Nick\AppData\Local\Programs\Python\Python310\lib\site-packages\drf_spectacular\openapi.py", line 914, in _map_serializer
    schema = self._map_basic_serializer(serializer, direction)
  File "C:\Users\Nick\AppData\Local\Programs\Python\Python310\lib\site-packages\drf_spectacular\openapi.py", line 1006, in _map_basic_serializer
    for field in serializer.fields.values():
  File "C:\Users\Nick\AppData\Local\Programs\Python\Python310\lib\site-packages\django\utils\functional.py", line 57, in __get__
    res = instance.__dict__[self.name] = self.func(instance)
  File "C:\Users\Nick\AppData\Local\Programs\Python\Python310\lib\site-packages\rest_framework\serializers.py", line 356, in fields
    for key, value in self.get_fields().items():
  File "C:\Users\Nick\AppData\Local\Programs\Python\Python310\lib\site-packages\rest_framework\serializers.py", line 1052, in get_fields
    field_names = self.get_field_names(declared_fields, info)
  File "C:\Users\Nick\AppData\Local\Programs\Python\Python310\lib\site-packages\rest_framework\serializers.py", line 1148, in get_field_names
    assert field_name in fields, (
AssertionError: The field 'advert_info' was declared on serializer ProposalSerializer, but has not been included in the 'fields' option.
2024-01-21 17:55:43,464 django.request ERROR    Internal Server Error: /api/schema/
Traceback (most recent call last):
  File "C:\Users\Nick\AppData\Local\Programs\Python\Python310\lib\site-packages\django\core\handlers\exception.py", line 55, in inner
    response = get_response(request)
  File "C:\Users\Nick\AppData\Local\Programs\Python\Python310\lib\site-packages\django\core\handlers\base.py", line 197, in _get_response
    response = wrapped_callback(request, *callback_args, **callback_kwargs)
  File "C:\Users\Nick\AppData\Local\Programs\Python\Python310\lib\site-packages\django\views\decorators\csrf.py", line 56, in wrapper_view
    return view_func(*args, **kwargs)
  File "C:\Users\Nick\AppData\Local\Programs\Python\Python310\lib\site-packages\django\views\generic\base.py", line 104, in view
    return self.dispatch(request, *args, **kwargs)
  File "C:\Users\Nick\AppData\Local\Programs\Python\Python310\lib\site-packages\rest_framework\views.py", line 509, in dispatch
    response = self.handle_exception(exc)
  File "C:\Users\Nick\AppData\Local\Programs\Python\Python310\lib\site-packages\rest_framework\views.py", line 469, in handle_exception
    self.raise_uncaught_exception(exc)
  File "C:\Users\Nick\AppData\Local\Programs\Python\Python310\lib\site-packages\rest_framework\views.py", line 480, in raise_uncaught_exception
    raise exc
  File "C:\Users\Nick\AppData\Local\Programs\Python\Python310\lib\site-packages\rest_framework\views.py", line 506, in dispatch
    response = handler(request, *args, **kwargs)
  File "C:\Users\Nick\AppData\Local\Programs\Python\Python310\lib\site-packages\drf_spectacular\views.py", line 83, in get
    return self._get_schema_response(request)
  File "C:\Users\Nick\AppData\Local\Programs\Python\Python310\lib\site-packages\drf_spectacular\views.py", line 91, in _get_schema_response
    data=generator.get_schema(request=request, public=self.serve_public),
  File "C:\Users\Nick\AppData\Local\Programs\Python\Python310\lib\site-packages\drf_spectacular\generators.py", line 268, in get_schema
    paths=self.parse(request, public),
  File "C:\Users\Nick\AppData\Local\Programs\Python\Python310\lib\site-packages\drf_spectacular\generators.py", line 239, in parse
    operation = view.schema.get_operation(
  File "C:\Users\Nick\AppData\Local\Programs\Python\Python310\lib\site-packages\drf_spectacular\utils.py", line 422, in get_operation
    return super().get_operation(path, path_regex, path_prefix, method, registry)
  File "C:\Users\Nick\AppData\Local\Programs\Python\Python310\lib\site-packages\drf_spectacular\openapi.py", line 98, in get_operation
    operation['responses'] = self._get_response_bodies()
  File "C:\Users\Nick\AppData\Local\Programs\Python\Python310\lib\site-packages\drf_spectacular\openapi.py", line 1355, in _get_response_bodies
    return {'200': self._get_response_for_code(response_serializers, '200', direction=direction)}
  File "C:\Users\Nick\AppData\Local\Programs\Python\Python310\lib\site-packages\drf_spectacular\openapi.py", line 1411, in _get_response_for_code
    component = self.resolve_serializer(serializer, direction)
  File "C:\Users\Nick\AppData\Local\Programs\Python\Python310\lib\site-packages\drf_spectacular\openapi.py", line 1585, in resolve_serializer
    component.schema = self._map_serializer(serializer, direction, bypass_extensions)
  File "C:\Users\Nick\AppData\Local\Programs\Python\Python310\lib\site-packages\drf_spectacular\openapi.py", line 914, in _map_serializer
    schema = self._map_basic_serializer(serializer, direction)
  File "C:\Users\Nick\AppData\Local\Programs\Python\Python310\lib\site-packages\drf_spectacular\openapi.py", line 1006, in _map_basic_serializer
    for field in serializer.fields.values():
  File "C:\Users\Nick\AppData\Local\Programs\Python\Python310\lib\site-packages\django\utils\functional.py", line 57, in __get__
    res = instance.__dict__[self.name] = self.func(instance)
  File "C:\Users\Nick\AppData\Local\Programs\Python\Python310\lib\site-packages\rest_framework\serializers.py", line 356, in fields
    for key, value in self.get_fields().items():
  File "C:\Users\Nick\AppData\Local\Programs\Python\Python310\lib\site-packages\rest_framework\serializers.py", line 1052, in get_fields
    field_names = self.get_field_names(declared_fields, info)
  File "C:\Users\Nick\AppData\Local\Programs\Python\Python310\lib\site-packages\rest_framework\serializers.py", line 1148, in get_field_names
    assert field_name in fields, (
AssertionError: The field 'advert_info' was declared on serializer ProposalSerializer, but has not been included in the 'fields' option.
2024-01-21 17:55:45,194 django.request ERROR    Internal Server Error: /api/schema/
Traceback (most recent call last):
  File "C:\Users\Nick\AppData\Local\Programs\Python\Python310\lib\site-packages\django\core\handlers\exception.py", line 55, in inner
    response = get_response(request)
  File "C:\Users\Nick\AppData\Local\Programs\Python\Python310\lib\site-packages\django\core\handlers\base.py", line 197, in _get_response
    response = wrapped_callback(request, *callback_args, **callback_kwargs)
  File "C:\Users\Nick\AppData\Local\Programs\Python\Python310\lib\site-packages\django\views\decorators\csrf.py", line 56, in wrapper_view
    return view_func(*args, **kwargs)
  File "C:\Users\Nick\AppData\Local\Programs\Python\Python310\lib\site-packages\django\views\generic\base.py", line 104, in view
    return self.dispatch(request, *args, **kwargs)
  File "C:\Users\Nick\AppData\Local\Programs\Python\Python310\lib\site-packages\rest_framework\views.py", line 509, in dispatch
    response = self.handle_exception(exc)
  File "C:\Users\Nick\AppData\Local\Programs\Python\Python310\lib\site-packages\rest_framework\views.py", line 469, in handle_exception
    self.raise_uncaught_exception(exc)
  File "C:\Users\Nick\AppData\Local\Programs\Python\Python310\lib\site-packages\rest_framework\views.py", line 480, in raise_uncaught_exception
    raise exc
  File "C:\Users\Nick\AppData\Local\Programs\Python\Python310\lib\site-packages\rest_framework\views.py", line 506, in dispatch
    response = handler(request, *args, **kwargs)
  File "C:\Users\Nick\AppData\Local\Programs\Python\Python310\lib\site-packages\drf_spectacular\views.py", line 83, in get
    return self._get_schema_response(request)
  File "C:\Users\Nick\AppData\Local\Programs\Python\Python310\lib\site-packages\drf_spectacular\views.py", line 91, in _get_schema_response
    data=generator.get_schema(request=request, public=self.serve_public),
  File "C:\Users\Nick\AppData\Local\Programs\Python\Python310\lib\site-packages\drf_spectacular\generators.py", line 268, in get_schema
    paths=self.parse(request, public),
  File "C:\Users\Nick\AppData\Local\Programs\Python\Python310\lib\site-packages\drf_spectacular\generators.py", line 239, in parse
    operation = view.schema.get_operation(
  File "C:\Users\Nick\AppData\Local\Programs\Python\Python310\lib\site-packages\drf_spectacular\utils.py", line 422, in get_operation
    return super().get_operation(path, path_regex, path_prefix, method, registry)
  File "C:\Users\Nick\AppData\Local\Programs\Python\Python310\lib\site-packages\drf_spectacular\openapi.py", line 98, in get_operation
    operation['responses'] = self._get_response_bodies()
  File "C:\Users\Nick\AppData\Local\Programs\Python\Python310\lib\site-packages\drf_spectacular\openapi.py", line 1355, in _get_response_bodies
    return {'200': self._get_response_for_code(response_serializers, '200', direction=direction)}
  File "C:\Users\Nick\AppData\Local\Programs\Python\Python310\lib\site-packages\drf_spectacular\openapi.py", line 1411, in _get_response_for_code
    component = self.resolve_serializer(serializer, direction)
  File "C:\Users\Nick\AppData\Local\Programs\Python\Python310\lib\site-packages\drf_spectacular\openapi.py", line 1585, in resolve_serializer
    component.schema = self._map_serializer(serializer, direction, bypass_extensions)
  File "C:\Users\Nick\AppData\Local\Programs\Python\Python310\lib\site-packages\drf_spectacular\openapi.py", line 914, in _map_serializer
    schema = self._map_basic_serializer(serializer, direction)
  File "C:\Users\Nick\AppData\Local\Programs\Python\Python310\lib\site-packages\drf_spectacular\openapi.py", line 1006, in _map_basic_serializer
    for field in serializer.fields.values():
  File "C:\Users\Nick\AppData\Local\Programs\Python\Python310\lib\site-packages\django\utils\functional.py", line 57, in __get__
    res = instance.__dict__[self.name] = self.func(instance)
  File "C:\Users\Nick\AppData\Local\Programs\Python\Python310\lib\site-packages\rest_framework\serializers.py", line 356, in fields
    for key, value in self.get_fields().items():
  File "C:\Users\Nick\AppData\Local\Programs\Python\Python310\lib\site-packages\rest_framework\serializers.py", line 1052, in get_fields
    field_names = self.get_field_names(declared_fields, info)
  File "C:\Users\Nick\AppData\Local\Programs\Python\Python310\lib\site-packages\rest_framework\serializers.py", line 1148, in get_field_names
    assert field_name in fields, (
AssertionError: The field 'advert_info' was declared on serializer ProposalSerializer, but has not been included in the 'fields' option.
2024-01-21 17:55:45,298 django.request ERROR    Internal Server Error: /api/schema/
Traceback (most recent call last):
  File "C:\Users\Nick\AppData\Local\Programs\Python\Python310\lib\site-packages\django\core\handlers\exception.py", line 55, in inner
    response = get_response(request)
  File "C:\Users\Nick\AppData\Local\Programs\Python\Python310\lib\site-packages\django\core\handlers\base.py", line 197, in _get_response
    response = wrapped_callback(request, *callback_args, **callback_kwargs)
  File "C:\Users\Nick\AppData\Local\Programs\Python\Python310\lib\site-packages\django\views\decorators\csrf.py", line 56, in wrapper_view
    return view_func(*args, **kwargs)
  File "C:\Users\Nick\AppData\Local\Programs\Python\Python310\lib\site-packages\django\views\generic\base.py", line 104, in view
    return self.dispatch(request, *args, **kwargs)
  File "C:\Users\Nick\AppData\Local\Programs\Python\Python310\lib\site-packages\rest_framework\views.py", line 509, in dispatch
    response = self.handle_exception(exc)
  File "C:\Users\Nick\AppData\Local\Programs\Python\Python310\lib\site-packages\rest_framework\views.py", line 469, in handle_exception
    self.raise_uncaught_exception(exc)
  File "C:\Users\Nick\AppData\Local\Programs\Python\Python310\lib\site-packages\rest_framework\views.py", line 480, in raise_uncaught_exception
    raise exc
  File "C:\Users\Nick\AppData\Local\Programs\Python\Python310\lib\site-packages\rest_framework\views.py", line 506, in dispatch
    response = handler(request, *args, **kwargs)
  File "C:\Users\Nick\AppData\Local\Programs\Python\Python310\lib\site-packages\drf_spectacular\views.py", line 83, in get
    return self._get_schema_response(request)
  File "C:\Users\Nick\AppData\Local\Programs\Python\Python310\lib\site-packages\drf_spectacular\views.py", line 91, in _get_schema_response
    data=generator.get_schema(request=request, public=self.serve_public),
  File "C:\Users\Nick\AppData\Local\Programs\Python\Python310\lib\site-packages\drf_spectacular\generators.py", line 268, in get_schema
    paths=self.parse(request, public),
  File "C:\Users\Nick\AppData\Local\Programs\Python\Python310\lib\site-packages\drf_spectacular\generators.py", line 239, in parse
    operation = view.schema.get_operation(
  File "C:\Users\Nick\AppData\Local\Programs\Python\Python310\lib\site-packages\drf_spectacular\utils.py", line 422, in get_operation
    return super().get_operation(path, path_regex, path_prefix, method, registry)
  File "C:\Users\Nick\AppData\Local\Programs\Python\Python310\lib\site-packages\drf_spectacular\openapi.py", line 98, in get_operation
    operation['responses'] = self._get_response_bodies()
  File "C:\Users\Nick\AppData\Local\Programs\Python\Python310\lib\site-packages\drf_spectacular\openapi.py", line 1355, in _get_response_bodies
    return {'200': self._get_response_for_code(response_serializers, '200', direction=direction)}
  File "C:\Users\Nick\AppData\Local\Programs\Python\Python310\lib\site-packages\drf_spectacular\openapi.py", line 1411, in _get_response_for_code
    component = self.resolve_serializer(serializer, direction)
  File "C:\Users\Nick\AppData\Local\Programs\Python\Python310\lib\site-packages\drf_spectacular\openapi.py", line 1585, in resolve_serializer
    component.schema = self._map_serializer(serializer, direction, bypass_extensions)
  File "C:\Users\Nick\AppData\Local\Programs\Python\Python310\lib\site-packages\drf_spectacular\openapi.py", line 914, in _map_serializer
    schema = self._map_basic_serializer(serializer, direction)
  File "C:\Users\Nick\AppData\Local\Programs\Python\Python310\lib\site-packages\drf_spectacular\openapi.py", line 1006, in _map_basic_serializer
    for field in serializer.fields.values():
  File "C:\Users\Nick\AppData\Local\Programs\Python\Python310\lib\site-packages\django\utils\functional.py", line 57, in __get__
    res = instance.__dict__[self.name] = self.func(instance)
  File "C:\Users\Nick\AppData\Local\Programs\Python\Python310\lib\site-packages\rest_framework\serializers.py", line 356, in fields
    for key, value in self.get_fields().items():
  File "C:\Users\Nick\AppData\Local\Programs\Python\Python310\lib\site-packages\rest_framework\serializers.py", line 1052, in get_fields
    field_names = self.get_field_names(declared_fields, info)
  File "C:\Users\Nick\AppData\Local\Programs\Python\Python310\lib\site-packages\rest_framework\serializers.py", line 1148, in get_field_names
    assert field_name in fields, (
AssertionError: The field 'advert_info' was declared on serializer ProposalSerializer, but has not been included in the 'fields' option.
2024-01-21 17:56:58,839 django.utils.autoreload INFO     C:\Users\Nick\Desktop\git\Advert-Project\mytestprj\advert\api\serializers.py changed, reloading.
2024-01-21 17:56:59,340 django.utils.autoreload INFO     Watching for file changes with StatReloader
2024-01-21 17:57:01,296 django.request WARNING  Not Found: /
2024-01-21 17:57:32,556 django.request ERROR    Internal Server Error: /api/content/proposals/
Traceback (most recent call last):
  File "C:\Users\Nick\AppData\Local\Programs\Python\Python310\lib\site-packages\django\core\handlers\exception.py", line 55, in inner
    response = get_response(request)
  File "C:\Users\Nick\AppData\Local\Programs\Python\Python310\lib\site-packages\django\core\handlers\base.py", line 197, in _get_response
    response = wrapped_callback(request, *callback_args, **callback_kwargs)
  File "C:\Users\Nick\AppData\Local\Programs\Python\Python310\lib\site-packages\django\views\decorators\csrf.py", line 56, in wrapper_view
    return view_func(*args, **kwargs)
  File "C:\Users\Nick\AppData\Local\Programs\Python\Python310\lib\site-packages\django\views\generic\base.py", line 104, in view
    return self.dispatch(request, *args, **kwargs)
  File "C:\Users\Nick\AppData\Local\Programs\Python\Python310\lib\site-packages\rest_framework\views.py", line 509, in dispatch
    response = self.handle_exception(exc)
  File "C:\Users\Nick\AppData\Local\Programs\Python\Python310\lib\site-packages\rest_framework\views.py", line 469, in handle_exception
    self.raise_uncaught_exception(exc)
  File "C:\Users\Nick\AppData\Local\Programs\Python\Python310\lib\site-packages\rest_framework\views.py", line 480, in raise_uncaught_exception
    raise exc
  File "C:\Users\Nick\AppData\Local\Programs\Python\Python310\lib\site-packages\rest_framework\views.py", line 506, in dispatch
    response = handler(request, *args, **kwargs)
  File "C:\Users\Nick\Desktop\git\Advert-Project\mytestprj\advert\api\views.py", line 223, in get
    "proposals": serializer.data
  File "C:\Users\Nick\AppData\Local\Programs\Python\Python310\lib\site-packages\rest_framework\serializers.py", line 768, in data
    ret = super().data
  File "C:\Users\Nick\AppData\Local\Programs\Python\Python310\lib\site-packages\rest_framework\serializers.py", line 253, in data
    self._data = self.to_representation(self.instance)
  File "C:\Users\Nick\AppData\Local\Programs\Python\Python310\lib\site-packages\rest_framework\serializers.py", line 686, in to_representation
    return [
  File "C:\Users\Nick\AppData\Local\Programs\Python\Python310\lib\site-packages\rest_framework\serializers.py", line 687, in <listcomp>
    self.child.to_representation(item) for item in iterable
  File "C:\Users\Nick\AppData\Local\Programs\Python\Python310\lib\site-packages\rest_framework\serializers.py", line 522, in to_representation
    ret[field.field_name] = field.to_representation(attribute)
  File "C:\Users\Nick\AppData\Local\Programs\Python\Python310\lib\site-packages\rest_framework\fields.py", line 1838, in to_representation
    return method(value)
  File "C:\Users\Nick\Desktop\git\Advert-Project\mytestprj\advert\api\serializers.py", line 17, in get_advert_info
    return get_advert_info(obj.advert)
  File "C:\Users\Nick\Desktop\git\Advert-Project\mytestprj\advert\api\serializers.py", line 25, in get_advert_info
    'num_proposals': Proposal.objects.filter(advert=obj.advert).count(),
AttributeError: 'Advert' object has no attribute 'advert'
2024-01-21 17:57:59,519 django.request WARNING  Not Found: /api/content/category
2024-01-21 17:58:12,807 django.request ERROR    Internal Server Error: /api/content/proposals/
Traceback (most recent call last):
  File "C:\Users\Nick\AppData\Local\Programs\Python\Python310\lib\site-packages\django\core\handlers\exception.py", line 55, in inner
    response = get_response(request)
  File "C:\Users\Nick\AppData\Local\Programs\Python\Python310\lib\site-packages\django\core\handlers\base.py", line 197, in _get_response
    response = wrapped_callback(request, *callback_args, **callback_kwargs)
  File "C:\Users\Nick\AppData\Local\Programs\Python\Python310\lib\site-packages\django\views\decorators\csrf.py", line 56, in wrapper_view
    return view_func(*args, **kwargs)
  File "C:\Users\Nick\AppData\Local\Programs\Python\Python310\lib\site-packages\django\views\generic\base.py", line 104, in view
    return self.dispatch(request, *args, **kwargs)
  File "C:\Users\Nick\AppData\Local\Programs\Python\Python310\lib\site-packages\rest_framework\views.py", line 509, in dispatch
    response = self.handle_exception(exc)
  File "C:\Users\Nick\AppData\Local\Programs\Python\Python310\lib\site-packages\rest_framework\views.py", line 469, in handle_exception
    self.raise_uncaught_exception(exc)
  File "C:\Users\Nick\AppData\Local\Programs\Python\Python310\lib\site-packages\rest_framework\views.py", line 480, in raise_uncaught_exception
    raise exc
  File "C:\Users\Nick\AppData\Local\Programs\Python\Python310\lib\site-packages\rest_framework\views.py", line 506, in dispatch
    response = handler(request, *args, **kwargs)
  File "C:\Users\Nick\Desktop\git\Advert-Project\mytestprj\advert\api\views.py", line 223, in get
    "proposals": serializer.data
  File "C:\Users\Nick\AppData\Local\Programs\Python\Python310\lib\site-packages\rest_framework\serializers.py", line 768, in data
    ret = super().data
  File "C:\Users\Nick\AppData\Local\Programs\Python\Python310\lib\site-packages\rest_framework\serializers.py", line 253, in data
    self._data = self.to_representation(self.instance)
  File "C:\Users\Nick\AppData\Local\Programs\Python\Python310\lib\site-packages\rest_framework\serializers.py", line 686, in to_representation
    return [
  File "C:\Users\Nick\AppData\Local\Programs\Python\Python310\lib\site-packages\rest_framework\serializers.py", line 687, in <listcomp>
    self.child.to_representation(item) for item in iterable
  File "C:\Users\Nick\AppData\Local\Programs\Python\Python310\lib\site-packages\rest_framework\serializers.py", line 522, in to_representation
    ret[field.field_name] = field.to_representation(attribute)
  File "C:\Users\Nick\AppData\Local\Programs\Python\Python310\lib\site-packages\rest_framework\fields.py", line 1838, in to_representation
    return method(value)
  File "C:\Users\Nick\Desktop\git\Advert-Project\mytestprj\advert\api\serializers.py", line 17, in get_advert_info
    return get_advert_info(obj.advert)
  File "C:\Users\Nick\Desktop\git\Advert-Project\mytestprj\advert\api\serializers.py", line 25, in get_advert_info
    'num_proposals': Proposal.objects.filter(advert=obj.advert).count(),
AttributeError: 'Advert' object has no attribute 'advert'
2024-01-21 18:02:08,847 django.utils.autoreload INFO     C:\Users\Nick\Desktop\git\Advert-Project\mytestprj\advert\api\serializers.py changed, reloading.
2024-01-21 18:02:09,367 django.utils.autoreload INFO     Watching for file changes with StatReloader
2024-01-21 18:02:26,546 django.request WARNING  Not Found: /
