2023-11-28 16:52:54,158 django.utils.autoreload INFO     Watching for file changes with StatReloader
2023-11-28 16:53:20,114 django.utils.autoreload INFO     C:\Users\Nick\Desktop\mytestprj\advert\advert\settings.py changed, reloading.
2023-11-28 16:53:24,039 django.utils.autoreload INFO     Watching for file changes with StatReloader
2023-11-28 16:53:25,687 django.request WARNING  Not Found: /
2023-11-28 16:10:55,867 django.utils.autoreload INFO     Watching for file changes with StatReloader
2023-11-28 16:20:08,262 django.utils.autoreload INFO     /app/advert/settings.py changed, reloading.
2023-11-28 16:20:09,052 django.utils.autoreload INFO     Watching for file changes with StatReloader
2023-11-28 16:20:30,776 django.utils.autoreload INFO     Watching for file changes with StatReloader
2023-11-28 16:21:02,820 django.request WARNING  Not Found: /
2023-11-28 16:21:05,329 django.request ERROR    Internal Server Error: /admin/
Traceback (most recent call last):
  File "/usr/local/lib/python3.8/site-packages/django/contrib/sessions/backends/base.py", line 187, in _get_session
    return self._session_cache
AttributeError: 'SessionStore' object has no attribute '_session_cache'

During handling of the above exception, another exception occurred:

Traceback (most recent call last):
  File "/usr/local/lib/python3.8/site-packages/django/db/backends/utils.py", line 89, in _execute
    return self.cursor.execute(sql, params)
psycopg2.errors.UndefinedTable: relation "django_session" does not exist
LINE 1: ...ession_data", "django_session"."expire_date" FROM "django_se...
                                                             ^


The above exception was the direct cause of the following exception:

Traceback (most recent call last):
  File "/usr/local/lib/python3.8/site-packages/django/core/handlers/exception.py", line 55, in inner
    response = get_response(request)
  File "/usr/local/lib/python3.8/site-packages/django/core/handlers/base.py", line 197, in _get_response
    response = wrapped_callback(request, *callback_args, **callback_kwargs)
  File "/usr/local/lib/python3.8/site-packages/django/contrib/admin/sites.py", line 261, in wrapper
    return self.admin_view(view, cacheable)(*args, **kwargs)
  File "/usr/local/lib/python3.8/site-packages/django/utils/decorators.py", line 134, in _wrapper_view
    response = view_func(request, *args, **kwargs)
  File "/usr/local/lib/python3.8/site-packages/django/views/decorators/cache.py", line 62, in _wrapper_view_func
    response = view_func(request, *args, **kwargs)
  File "/usr/local/lib/python3.8/site-packages/django/contrib/admin/sites.py", line 230, in inner
    if not self.has_permission(request):
  File "/usr/local/lib/python3.8/site-packages/django/contrib/admin/sites.py", line 203, in has_permission
    return request.user.is_active and request.user.is_staff
  File "/usr/local/lib/python3.8/site-packages/django/utils/functional.py", line 266, in inner
    self._setup()
  File "/usr/local/lib/python3.8/site-packages/django/utils/functional.py", line 419, in _setup
    self._wrapped = self._setupfunc()
  File "/usr/local/lib/python3.8/site-packages/django/contrib/auth/middleware.py", line 25, in <lambda>
    request.user = SimpleLazyObject(lambda: get_user(request))
  File "/usr/local/lib/python3.8/site-packages/django/contrib/auth/middleware.py", line 11, in get_user
    request._cached_user = auth.get_user(request)
  File "/usr/local/lib/python3.8/site-packages/django/contrib/auth/__init__.py", line 191, in get_user
    user_id = _get_user_session_key(request)
  File "/usr/local/lib/python3.8/site-packages/django/contrib/auth/__init__.py", line 60, in _get_user_session_key
    return get_user_model()._meta.pk.to_python(request.session[SESSION_KEY])
  File "/usr/local/lib/python3.8/site-packages/django/contrib/sessions/backends/base.py", line 53, in __getitem__
    return self._session[key]
  File "/usr/local/lib/python3.8/site-packages/django/contrib/sessions/backends/base.py", line 192, in _get_session
    self._session_cache = self.load()
  File "/usr/local/lib/python3.8/site-packages/django/contrib/sessions/backends/db.py", line 42, in load
    s = self._get_session_from_db()
  File "/usr/local/lib/python3.8/site-packages/django/contrib/sessions/backends/db.py", line 32, in _get_session_from_db
    return self.model.objects.get(
  File "/usr/local/lib/python3.8/site-packages/django/db/models/manager.py", line 87, in manager_method
    return getattr(self.get_queryset(), name)(*args, **kwargs)
  File "/usr/local/lib/python3.8/site-packages/django/db/models/query.py", line 633, in get
    num = len(clone)
  File "/usr/local/lib/python3.8/site-packages/django/db/models/query.py", line 380, in __len__
    self._fetch_all()
  File "/usr/local/lib/python3.8/site-packages/django/db/models/query.py", line 1881, in _fetch_all
    self._result_cache = list(self._iterable_class(self))
  File "/usr/local/lib/python3.8/site-packages/django/db/models/query.py", line 91, in __iter__
    results = compiler.execute_sql(
  File "/usr/local/lib/python3.8/site-packages/django/db/models/sql/compiler.py", line 1562, in execute_sql
    cursor.execute(sql, params)
  File "/usr/local/lib/python3.8/site-packages/django/db/backends/utils.py", line 102, in execute
    return super().execute(sql, params)
  File "/usr/local/lib/python3.8/site-packages/django/db/backends/utils.py", line 67, in execute
    return self._execute_with_wrappers(
  File "/usr/local/lib/python3.8/site-packages/django/db/backends/utils.py", line 80, in _execute_with_wrappers
    return executor(sql, params, many, context)
  File "/usr/local/lib/python3.8/site-packages/django/db/backends/utils.py", line 89, in _execute
    return self.cursor.execute(sql, params)
  File "/usr/local/lib/python3.8/site-packages/django/db/utils.py", line 91, in __exit__
    raise dj_exc_value.with_traceback(traceback) from exc_value
  File "/usr/local/lib/python3.8/site-packages/django/db/backends/utils.py", line 89, in _execute
    return self.cursor.execute(sql, params)
django.db.utils.ProgrammingError: relation "django_session" does not exist
LINE 1: ...ession_data", "django_session"."expire_date" FROM "django_se...
                                                             ^

2023-11-28 16:21:05,562 django.request ERROR    Internal Server Error: /admin/
Traceback (most recent call last):
  File "/usr/local/lib/python3.8/site-packages/django/contrib/sessions/backends/base.py", line 187, in _get_session
    return self._session_cache
AttributeError: 'SessionStore' object has no attribute '_session_cache'

During handling of the above exception, another exception occurred:

Traceback (most recent call last):
  File "/usr/local/lib/python3.8/site-packages/django/db/backends/utils.py", line 89, in _execute
    return self.cursor.execute(sql, params)
psycopg2.errors.UndefinedTable: relation "django_session" does not exist
LINE 1: ...ession_data", "django_session"."expire_date" FROM "django_se...
                                                             ^


The above exception was the direct cause of the following exception:

Traceback (most recent call last):
  File "/usr/local/lib/python3.8/site-packages/django/core/handlers/exception.py", line 55, in inner
    response = get_response(request)
  File "/usr/local/lib/python3.8/site-packages/django/core/handlers/base.py", line 197, in _get_response
    response = wrapped_callback(request, *callback_args, **callback_kwargs)
  File "/usr/local/lib/python3.8/site-packages/django/contrib/admin/sites.py", line 261, in wrapper
    return self.admin_view(view, cacheable)(*args, **kwargs)
  File "/usr/local/lib/python3.8/site-packages/django/utils/decorators.py", line 134, in _wrapper_view
    response = view_func(request, *args, **kwargs)
  File "/usr/local/lib/python3.8/site-packages/django/views/decorators/cache.py", line 62, in _wrapper_view_func
    response = view_func(request, *args, **kwargs)
  File "/usr/local/lib/python3.8/site-packages/django/contrib/admin/sites.py", line 230, in inner
    if not self.has_permission(request):
  File "/usr/local/lib/python3.8/site-packages/django/contrib/admin/sites.py", line 203, in has_permission
    return request.user.is_active and request.user.is_staff
  File "/usr/local/lib/python3.8/site-packages/django/utils/functional.py", line 266, in inner
    self._setup()
  File "/usr/local/lib/python3.8/site-packages/django/utils/functional.py", line 419, in _setup
    self._wrapped = self._setupfunc()
  File "/usr/local/lib/python3.8/site-packages/django/contrib/auth/middleware.py", line 25, in <lambda>
    request.user = SimpleLazyObject(lambda: get_user(request))
  File "/usr/local/lib/python3.8/site-packages/django/contrib/auth/middleware.py", line 11, in get_user
    request._cached_user = auth.get_user(request)
  File "/usr/local/lib/python3.8/site-packages/django/contrib/auth/__init__.py", line 191, in get_user
    user_id = _get_user_session_key(request)
  File "/usr/local/lib/python3.8/site-packages/django/contrib/auth/__init__.py", line 60, in _get_user_session_key
    return get_user_model()._meta.pk.to_python(request.session[SESSION_KEY])
  File "/usr/local/lib/python3.8/site-packages/django/contrib/sessions/backends/base.py", line 53, in __getitem__
    return self._session[key]
  File "/usr/local/lib/python3.8/site-packages/django/contrib/sessions/backends/base.py", line 192, in _get_session
    self._session_cache = self.load()
  File "/usr/local/lib/python3.8/site-packages/django/contrib/sessions/backends/db.py", line 42, in load
    s = self._get_session_from_db()
  File "/usr/local/lib/python3.8/site-packages/django/contrib/sessions/backends/db.py", line 32, in _get_session_from_db
    return self.model.objects.get(
  File "/usr/local/lib/python3.8/site-packages/django/db/models/manager.py", line 87, in manager_method
    return getattr(self.get_queryset(), name)(*args, **kwargs)
  File "/usr/local/lib/python3.8/site-packages/django/db/models/query.py", line 633, in get
    num = len(clone)
  File "/usr/local/lib/python3.8/site-packages/django/db/models/query.py", line 380, in __len__
    self._fetch_all()
  File "/usr/local/lib/python3.8/site-packages/django/db/models/query.py", line 1881, in _fetch_all
    self._result_cache = list(self._iterable_class(self))
  File "/usr/local/lib/python3.8/site-packages/django/db/models/query.py", line 91, in __iter__
    results = compiler.execute_sql(
  File "/usr/local/lib/python3.8/site-packages/django/db/models/sql/compiler.py", line 1562, in execute_sql
    cursor.execute(sql, params)
  File "/usr/local/lib/python3.8/site-packages/django/db/backends/utils.py", line 102, in execute
    return super().execute(sql, params)
  File "/usr/local/lib/python3.8/site-packages/django/db/backends/utils.py", line 67, in execute
    return self._execute_with_wrappers(
  File "/usr/local/lib/python3.8/site-packages/django/db/backends/utils.py", line 80, in _execute_with_wrappers
    return executor(sql, params, many, context)
  File "/usr/local/lib/python3.8/site-packages/django/db/backends/utils.py", line 89, in _execute
    return self.cursor.execute(sql, params)
  File "/usr/local/lib/python3.8/site-packages/django/db/utils.py", line 91, in __exit__
    raise dj_exc_value.with_traceback(traceback) from exc_value
  File "/usr/local/lib/python3.8/site-packages/django/db/backends/utils.py", line 89, in _execute
    return self.cursor.execute(sql, params)
django.db.utils.ProgrammingError: relation "django_session" does not exist
LINE 1: ...ession_data", "django_session"."expire_date" FROM "django_se...
                                                             ^

2023-11-29 08:44:24,457 django.utils.autoreload INFO     Watching for file changes with StatReloader
2023-11-29 09:11:09,349 django.utils.autoreload INFO     Watching for file changes with StatReloader
2023-11-29 09:11:35,041 django.utils.autoreload INFO     Watching for file changes with StatReloader
2023-11-29 09:13:34,053 django.request WARNING  Not Found: /
2023-11-29 09:13:34,182 django.request WARNING  Not Found: /favicon.ico
2024-01-11 17:49:12,085 django.utils.autoreload INFO     Watching for file changes with StatReloader
2024-01-11 17:49:14,163 django.request WARNING  Not Found: /
2024-01-11 17:51:35,770 django.utils.autoreload INFO     Watching for file changes with StatReloader
2024-01-11 17:51:37,254 django.request WARNING  Not Found: /
